File: au3-0001.pxt.vms
VAMAS Surface Chemical Analysis Standard Data Transfer Format 1988 May 4

R4000LI-4MS241_4ES243
Zakaria
Not Specified
0
NORM
REGULAR
0
3
Slice
d
Theta
d
X-Axis
d
0
0
0
0
2
survey 655
Au
2023
4
13
2
3
31
0
7
Casa Info Follows
0
0
0
0
Au
Lens Mode = Transmission
XPS
1
0
0
Sync
655
1e+037
1e+037
1e+037
1e+037
1e+037
FAT
100
1e+037
1e+037
1e+037
1e+037
1e+037
1e+037
1e+037
survey 655

-1
Kinetic Energy
eV
55
0.5
2
Intensity
d
Transmission
d
pulse counting
0.067
1e+037
1e+037
0
0
0
13844.7
12405.8
13365.1
15925.7
14376.9
14764.5
13798.7
16209.9
13437.3
13489.9
12880.5
13389.7
11814.5
13797.1
12162.8
14529.6
12248.2
12525.8
12691.6
12382.9
14772.7
11413.8
13877.5
12933.1
13831.5
13199.2
12312.2
11872
12995.5
12875.6
14036.9
14247.1
13895.6
13350.3
12890.4
14125.6
13854.5
12151.3
13103.9
14022.1
13918.6
11714.4
11706.1
11152.6
13370
12532.3
10723.9
10057.1
10456.2
10331.4
10980.2
8404.7
10001.2
10227.9
9853.4
7478.33
9014.07
6410.7
10812.6
8061.42
8128.76
7353.5
7383.07
7870.89
7537.46
7916.88
9579.1
7205.67
8774.27
6826.26
5970.51
7798.62
6128.19
7238.53
8196.11
8403.06
7512.82
7412.63
7629.44
7116.98
6683.36
5983.65
6568.38
7108.77
7371.57
6813.12
7417.56
7908.67
8035.14
6806.55
7805.19
7716.49
8159.97
6443.55
6837.75
7052.92
7759.2
6739.2
7741.13
6317.08
6410.7
6069.06
7598.23
8051.57
7151.47
6711.28
7200.75
6136.4
7415.92
9079.77
7113.69
7197.46
7493.11
7015.14
7412.63
8795.62
6724.42
7315.72
7010.22
6722.78
7374.85
6161.04
6394.28
6832.83
7723.06
6119.98
5535.25
5318.44
7575.24
7545.67
6831.18
6921.52
6983.94
7279.59
7208.96
6844.32
8557.46
7836.4
6898.53
7857.75
8260.16
8087.7
6464.9
6277.66
5655.15
7590.02
6023.07
5978.72
7374.85
5714.28
6184.04
6069.06
6024.71
6528.96
7281.23
7910.31
6157.76
5587.81
7271.38
4968.58
7108.77
7435.63
6126.55
6234.95
6502.68
5980.37
6730.99
6612.73
5269.16
6105.2
6185.68
5052.35
5793.12
7189.25
7967.8
6096.98
5507.32
7788.76
6445.19
5706.07
6857.46
5504.04
6264.52
7046.35
6126.55
6934.66
6540.46
6295.73
5336.5
7529.25
5272.45
6752.34
6404.13
5302.01
5655.15
5658.43
5725.78
6816.4
5535.25
6868.96
6468.19
5648.58
7517.75
5581.24
4848.68
5487.61
6624.23
4600.66
6200.46
6520.75
4860.18
6786.84
5747.13
5398.92
6681.72
7215.53
4957.08
6816.4
5972.15
6326.93
4865.1
6404.13
5812.83
6169.25
6128.19
5416.99
6520.75
4794.48
5287.23
5876.89
6683.36
4973.51
6014.86
5827.61
4107.91
4888.1
4339.5
4746.84
5469.55
4883.17
5136.12
5247.81
5180.46
5576.31
5530.32
5743.84
6138.05
5096.7
5536.89
6392.63
5674.86
6096.98
6363.07
6632.44
5725.78
5124.62
5132.83
6423.84
5129.55
6256.31
6057.56
5352.93
7892.24
5832.54
4922.59
4722.21
5037.57
6655.44
6330.22
4086.56
5078.63
5267.52
6821.33
6008.29
6198.82
5254.38
4599.02
5264.23
5288.87
5042.49
5538.53
5558.24
4686.07
7218.82
5034.28
5528.68
5970.51
4548.1
5392.35
5236.31
4217.96
4769.84
5960.66
5487.61
5282.3
6023.07
6285.87
4927.52
6783.55
5926.16
5348
5149.26
4190.03
5484.33
4232.74
3840.18
5377.57
5280.66
5413.7
6568.38
5760.27
4985.01
6602.88
5029.35
5484.33
5359.5
5200.17
5193.6
5597.66
4694.28
4705.78
4646.65
5364.43
5127.9
6121.62
5124.62
4375.64
4217.96
6481.33
5004.72
6182.39
5287.23
5517.18
5037.57
4240.95
6080.56
5334.86
4993.22
4980.08
5290.51
5753.7
6119.98
5413.7
5829.25
5280.66
5351.29
5039.21
5398.92
5748.77
5231.38
4912.74
5553.31
4735.35
5786.55
5175.54
5778.34
5162.4
4893.03
4778.05
5714.28
5026.07
5625.58
5308.58
4646.65
4224.53
6279.3
5993.51
6303.94
5449.84
5678.14
5701.14
4934.09
5272.45
5568.1
6652.15
5857.18
6116.69
5556.6
4608.87
5766.84
5438.34
4521.82
5584.52
4870.03
6215.24
4891.38
5985.29
5615.73
6050.99
6768.77
5162.4
5508.97
5367.71
5180.46
4952.16
4326.36
5919.59
5563.17
5099.98
5456.41
6479.69
5934.38
6060.85
5755.34
5924.52
5945.87
5288.87
5274.09
5671.57
4700.85
5323.36
4658.15
5103.27
4802.69
4485.68
5528.68
5172.25
5911.38
4835.54
6486.26
5103.27
5154.18
5211.67
5886.74
5763.55
5155.83
5449.84
5748.77
5783.26
4603.95
5531.96
6042.78
5315.15
4111.19
4341.14
5776.69
4735.35
5663.36
5026.07
6276.02
5219.88
5451.48
5678.14
5145.97
5257.66
4879.89
5853.89
5574.67
5091.77
5239.59
4122.69
6070.7
5065.49
6234.95
5037.57
5170.61
5520.46
6180.75
5242.88
4983.36
6149.54
6059.21
4822.4
5311.87
5932.73
5219.88
5533.6
4502.11
4705.78
5919.59
5530.32
5155.83
5479.4
5017.86
5817.76
6165.97
5587.81
5650.22
5756.98
5558.24
6294.08
5017.86
5513.89
6177.47
5622.3
6101.91
6134.76
4679.5
5210.03
5996.79
5118.05
4794.48
5778.34
6231.67
6351.57
7156.4
7005.29
6583.17
8040.07
6867.32
6469.83
6336.79
5983.65
5436.7
6719.49
5141.04
5888.38
5380.85
5812.83
4968.58
5356.21
4061.92
4957.08
5150.9
5127.9
4947.23
4735.35
4472.54
5495.83
5293.8
6284.23
4904.52
4539.89
5665
5444.91
6458.33
5487.61
6652.15
6435.34
7402.78
7277.95
7655.72
8045
6236.6
7445.48
7025
6011.57
5584.52
4727.13
5819.4
4932.45
3894.38
5683.07
3789.26
5584.52
4694.28
4817.47
4847.04
5814.47
4525.1
5646.94
5653.51
4738.63
4610.52
4906.17
4595.73
5982.01
4784.62
4700.85
5096.7
5960.66
4160.47
4633.51
4623.66
4331.29
4429.84
4469.26
4778.05
5239.59
4157.18
3720.28
5408.77
4819.11
5067.13
4280.37
5091.77
4544.81
3759.7
4630.23
3700.57
4454.48
4584.23
5850.61
5272.45
5458.05
4960.37
4886.46
4776.41
4912.74
4743.56
5742.2
5006.36
4198.25
4927.52
4843.75
5952.44
5970.51
4410.13
3560.95
4554.67
5063.85
4196.6
4801.05
4472.54
4917.66
4625.3
4521.82
4561.24
5142.69
4109.55
4661.43
3891.1
4493.9
4536.6
4309.94
3823.75
5665
4888.1
5093.41
3771.19
4042.21
5292.16
5405.49
5627.23
4295.15
4329.65
4079.99
3444.34
4214.67
6287.51
6187.32
8938.52
8697.07
12427.2
13154.8
8587.02
6244.81
3667.72
4672.93
4942.3
4691
4339.5
4372.35
3148.68
4998.15
4830.61
4676.22
3603.66
3542.89
4148.97
4556.31
4796.12
4395.35
4710.71
4554.67
4400.27
4078.34
3902.59
4162.11
4605.59
4645.01
4129.26
3716.99
4756.7
5523.75
5053.99
4677.86
4424.91
5568.1
4784.62
3994.58
5380.85
5277.37
5359.5
3556.03
3682.5
4075.06
4628.58
3812.26
4034
4782.98
5392.35
5001.43
4966.94
4819.11
4965.3
5070.42
5016.21
4538.24
5086.84
4006.07
4858.53
5665
4809.26
4888.1
5444.91
6318.72
5371
4439.69
4388.78
5034.28
4065.2
4899.6
3232.45
4232.74
4270.52
4851.96
5034.28
4158.83
4053.71
4431.48
3508.39
5029.35
4751.77
3923.95
4142.4
3112.55
5387.42
6336.79
5321.72
4308.29
5011.29
5477.76
4541.53
3687.43
5633.8
4942.3
5382.49
3345.79
5078.63
4572.74
4833.9
4523.46
3874.67
4227.81
5270.8
4548.1
4022.5
4643.37
5293.8
4807.62
4592.45
4774.77
3866.46
4147.33
3531.39
4270.52
4630.23
3736.7
5980.37
5384.14
6785.19
4916.02
5967.23
3735.06
4871.67
5658.43
5886.74
4925.88
5303.65
4858.53
5993.51
4853.61
5510.61
5413.7
5719.21
4226.17
4275.44
5226.45
5091.77
4157.18
4820.76
5681.43
4771.48
4584.23
5707.71
5098.34
4866.75
5476.12
6167.61
4398.63
6042.78
5369.35
5697.85
4153.9
4953.8
5279.02
6105.2
6182.39
5045.78
5671.57
5691.28
5328.29
4421.63
5594.38
5870.32
5310.22
5574.67
4347.71
4781.34
5720.85
5001.43
6422.2
5646.94
5252.74
6096.98
4523.46
5334.86
5474.47
6671.86
4924.23
4070.13
5504.04
4842.11
4858.53
5822.68
5205.1
4553.03
4341.14
5775.05
5490.9
7254.95
5170.61
5645.29
6556.89
5678.14
6558.53
5556.6
4861.82
4792.83
6271.09
4203.17
5185.39
5467.9
6108.48
6942.87
4782.98
5285.59
6376.21
6200.46
5954.09
6461.62
5642.01
6253.02
5536.89
6065.78
5871.96
5771.77
4914.38
5495.83
7225.39
7254.95
6305.58
5730.7
5055.63
5913.02
5929.45
7034.85
4838.82
5320.08
5881.81
6530.6
5147.61
5600.95
6230.03
6926.45
5876.89
6722.78
6813.12
5844.04
6376.21
6041.14
6326.93
6087.13
6008.29
8035.14
6576.6
6721.14
6960.94
5694.57
6307.22
6271.09
5855.53
5760.27
5628.87
7061.13
6392.63
6850.89
7281.23
6333.5
7082.49
6576.6
7171.18
6193.89
6757.27
6119.98
6384.42
6078.92
5707.71
6230.03
7949.73
7223.74
7023.36
6666.93
5952.44
7069.35
6908.38
7463.55
7084.13
7644.22
5485.97
6609.45
7389.64
7974.37
6818.04
6463.26
6251.38
7911.95
8187.89
7603.16
8389.92
7920.17
5425.2
7672.15
7524.32
8375.14
8961.51
8340.65
6366.35
7320.65
6847.61
6739.2
7885.67
7974.37
5599.3
7534.18
8018.72
6749.06
7342
6694.86
6663.65
5380.85
7636.01
5880.17
7486.54
6854.18
7637.65
6836.11
8210.89
9124.12
7688.57
8767.7
7990.79
8802.19
8522.97
9329.44
7836.4
7455.34
9247.31
10405.3
8417.84
8435.91
10388.9
7432.34
8950.02
8271.66
7708.28
8429.34
8877.75
9536.39
7394.56
8780.84
8289.73
6597.95
9508.47
9311.37
6906.74
8789.05
8871.18
9588.95
8194.46
11509
8053.21
7976.01
9804.12
8046.64
8342.29
9336.01
8769.34
7903.74
8948.37
8407.99
8733.21
9927.31
9171.75
9004.22
8598.52
9288.37
9884.6
7770.7
9046.92
9574.17
8432.63
8348.86
8943.45
7948.09
8319.29
7330.51
9051.85
7447.12
7989.15
5993.51
5564.81
6156.11
7521.04
6182.39
7693.5
7631.08
6175.82
6865.68
6773.7
5967.23
7207.32
7125.19
10503.8
14043.4
37725.1
69934.6
53484.9
18882.3
7378.14
6814.76
12778.7
27198.3
83432.7
88235.4
30925.1
7645.87
3357.28
1943.08
1663.86
1461.83
1107.05
1259.8
1144.83
1156.32
1484.83
1524.25
1133.33
921.446
1305.79
1302.51
698.065
1167.82
1052.85
975.649
1248.3
752.268
857.388
859.031
926.374
408.984
936.229
837.678
714.49
819.611
1039.71
574.877
413.912
482.897
762.123
1011.78
454.974
785.118
1565.31
392.559
895.166
1430.62
343.284
1179.32
1084.05
1902.02
1011.78
955.939
1085.7
1547.24
1136.61
829.466
997.001
2335.64
1369.85
757.195
661.93
983.861
1215.45
967.436
1130.04
801.543
594.587
482.897
767.05
762.123
323.574
768.693
326.859
479.612
320.289
394.202
548.597
349.854
330.144
257.873
428.694
395.844
578.162
262.801
108.405
535.457
392.559
303.864
218.453
279.226
252.946
591.302
272.656
313.719
177.391
558.452
581.447
351.496
589.66
264.444
771.978
338.356
967.436
136.328
208.598
583.09
295.651
440.192
459.902
195.458
528.887
517.389
893.523
473.042
500.964
390.916
535.457
706.278
290.724
519.032
412.269
647.147
298.936
343.284
606.085
353.139
300.579
634.007
512.462
822.896
418.839
415.554
537.1
801.543
739.128
1174.39
303.864
356.424
174.106
476.327
269.371
433.622
678.355
461.544
443.477
635.65
474.684
372.849
666.858
463.187
399.129
931.301
372.849
351.496
609.37
1151.4
1557.1
1898.74
1000.29
1240.09
1701.64
1176.03
1971.01
1325.5
2378.35
2108.98
1105.41
591.302
231.593
344.926
310.434
149.468
70.6278
141.256
83.7678
72.2703
72.2703
65.7003
170.821
1
Au 4f 655
Au
2023
4
13
2
3
31
0
7
Casa Info Follows
0
0
0
0
Au
Lens Mode = Transmission
XPS
1
0
0
Sync
655
1e+037
1e+037
1e+037
1e+037
1e+037
FAT
100
1e+037
1e+037
1e+037
1e+037
1e+037
1e+037
1e+037
Au 4f 655

-1
Kinetic Energy
eV
562
0.1
2
Intensity
d
Transmission
d
pulse counting
0.2
3
1e+037
1e+037
1e+037
1e+037
0
282
0
1
0
1
60107.5
1
61396.9
1
61533.2
1
63693.1
1
67828.9
1
67858.5
1
60623.3
1
59122
1
64157.9
1
63491.1
1
60708.7
1
66357.3
1
61653.1
1
56196.7
1
60046.7
1
59987.6
1
60646.3
1
61763.2
1
61171.9
1
58839.5
1
66682.5
1
64194.1
1
59951.5
1
62321.6
1
59806.9
1
58951.2
1
62893.2
1
64915.1
1
65297.8
1
65304.4
1
67886.4
1
69501
1
66631.6
1
70465.2
1
69052.6
1
70235.2
1
65586.9
1
72539.6
1
68627.2
1
70171.2
1
67554.6
1
67472.5
1
69310.5
1
70905.4
1
77376.8
1
76310.8
1
82874.3
1
88833.3
1
97085.3
1
100654
1
114660
1
126877
1
142555
1
166248
1
212092
1
266663
1
336067
1
422924
1
533332
1
618767
1
686167
1
739228
1
755594
1
715219
1
644841
1
546705
1
451379
1
344772
1
275343
1
212002
1
161148
1
129237
1
108507
1
95025.6
1
86606.1
1
77468.8
1
73697.6
1
66242.3
1
66951.8
1
69210.3
1
65422.7
1
68881.8
1
69849.2
1
74155.9
1
83600.3
1
86560.1
1
95480.5
1
111819
1
135857
1
164123
1
190293
1
254884
1
328509
1
432295
1
562527
1
690434
1
812582
1
915213
1
974556
1
961223
1
909648
1
794993
1
661316
1
517613
1
401529
1
280336
1
204420
1
152901
1
111823
1
81810
1
63882
1
54064.7
1
44791.1
1
40530.5
1
35451.9
1
27424.9
1
27806
1
22374.2
1
24033.2
1
21667.9
1
20225.8
1
17844.2
1
18176
1
17744
1
16157.3
1
17808.1
1
14792.4
1
14999.4
1
14161.7
1
12862.5
1
14012.2
1
13585.2
1
14186.3
1
12281
1
14225.7
1
12379.6
1
10889.8
1
11592.8
1
11206.8
1
11449.9
1
11581.3
1
end of experiment