File: sh_all.vms
VAMAS Surface Chemical Analysis Standard Data Transfer Format 1988 May 4
Not Specified
Kratos Axis
Not Specified
Not Specified
3
Casa Info Follows CasaXPS Version 2.3.19rev1.0m
0
SourceAnalyserAngle: Not Specified
MAP
REGULAR
8
0
0
0
2
Data Set
d
Original Index
d
0
0
0
0
43
survey/2
sh1
2023
6
9
15
16
29
0
9
Casa Info Follows
0
0
0
0
sh1.vms Dir:D:\Google Drive\1 Academic\0 Berkeley\0 Long\B30 XPS\20230609 march of the pafs\
   XPS     Spectrum    Lens Mode:Hybrid   Resolution:Pass energy 160   Iris(Aper):slot(Slot)
   Acqn. Time(s): 121        Sweeps: 1        Anode:Mono(Al (Mono))(75 W)   Step(meV): 1000.0
   Dwell Time(ms): 100        Charge Neutraliser :On   Acquired On :23/06/09 15:16:29
XPS
82
2
0
0
Mono(Al (Mono))
1486.69
75
1e+037
1e+037
6000
6000
1e+037
1e+037
FAT
160
1e+037
-4.46
0
1e+037
1e+037
1e+037
1e+037
Wide
None
-1
Kinetic Energy
eV
286.69
1
2
Intensity
d
Transmission
d
pulse counting
0.1
1
0
1e+037
1e+037
1e+037
1
MFP Exponent
d
-0.7414
1
27.6167
7034
7161
7240
7121
7201
7214
7268
7316
7250
7264
7227
7190
7046
7087
7067
7149
7155
7033
7114
7078
7064
7169
7121
6962
7136
7223
7047
7043
7096
7264
7203
7135
7121
7052
7040
7234
7184
7203
7166
7159
7196
7272
7397
7218
7059
7286
7192
7234
7127
7057
7043
7052
7053
7226
7204
7003
7001
6842
6950
6997
6800
6825
6782
6827
6741
6638
6624
6527
6418
6594
6649
6494
6509
6514
6591
6523
6597
6534
6476
6579
6661
6544
6629
6649
6705
6584
6703
6684
6767
6740
6659
6805
6705
6813
6753
6764
6668
6612
6659
6639
6727
6741
6663
6659
6653
6687
6671
6720
6703
6928
7075
7495
7638
7793
7813
7681
7527
7356
7082
7148
7029
6911
6647
6313
6276
6067
5903
5677
5693
5651
5599
5599
5706
5530
5588
5616
5618
5572
5688
5573
5583
5701
5667
5547
5562
5554
5534
5612
5533
5507
5554
5577
5574
5610
5563
5614
5602
5574
5535
5511
5633
5649
5540
5642
5640
5575
5646
5654
5587
5786
5822
5694
5807
5845
5717
5827
5693
5808
5883
5839
5917
5861
5897
5861
5864
5890
5923
5884
5950
5952
6028
5957
6006
6061
5987
6057
6001
5939
6052
6173
6205
6159
6110
6236
6194
6202
6175
6066
6008
6084
6088
5942
5932
5999
6066
5967
5959
5922
6050
6103
6269
6324
6337
6576
6684
6612
6687
6478
6296
6300
6047
6074
5866
5815
5836
5827
5620
5615
5608
5601
5461
5579
5483
5611
5668
5644
5674
5586
5626
5568
5676
5681
5659
5648
5740
5681
5657
5706
5665
5679
5738
5720
5698
5643
5621
5661
5726
5750
5737
5628
5649
5739
5839
5867
5734
5798
5840
5833
5797
5760
5798
5801
5808
5731
5766
5748
5777
5793
5831
5902
5853
5834
5767
5853
5976
6000
5817
5944
5976
6051
5958
5926
5850
5856
5846
5827
5835
5868
5820
5835
5917
5898
5885
5911
6007
6057
6001
5938
6049
6004
5977
6001
6013
5970
5955
5947
5945
5923
5971
5935
6000
6151
6110
5862
5961
5958
6062
6167
6089
6033
6084
5947
6074
6059
6089
6135
6045
6105
6106
6114
6106
6154
6155
6201
6106
6127
6145
6114
6124
6177
6176
6191
6152
6256
6276
6164
6246
6208
6284
6366
6398
6355
6379
6436
6446
6428
6403
6297
6228
6337
6191
6157
6185
6141
6093
6223
6055
6156
6058
6146
6149
6127
6173
6235
6094
5979
5963
6010
6102
6061
6111
6070
6232
6087
6140
6146
6074
6149
6196
6163
6132
6210
6253
6245
6196
6243
6138
6171
6205
6176
6269
6295
6178
6208
6226
6118
6242
6267
6246
6198
6255
6236
6268
6292
6364
6329
6345
6439
6427
6270
6359
6421
6295
6396
6461
6456
6375
6342
6392
6380
6414
6434
6587
6579
6321
6374
6384
6500
6459
6400
6430
6396
6465
6370
6488
6545
6515
6539
6496
6397
6446
6589
6520
6493
6604
6601
6582
6624
6673
6660
6552
6611
6589
6610
6503
6653
6538
6542
6711
6569
6461
6635
6782
7018
7316
7824
8003
7871
7440
7081
6801
6548
6453
6422
6312
6322
6315
6367
6364
6409
6310
6397
6452
6417
6232
6204
6233
6337
6167
6242
6287
6276
6162
6258
6289
6126
6127
6138
6109
6254
6512
7003
7727
8666
9068
8852
7915
6958
6311
5778
5558
5568
5543
5430
5419
5412
5388
5459
5298
5363
5238
5301
5347
5229
5224
5288
5249
5300
5326
5347
5390
5417
5485
5344
5340
5242
5401
5349
5311
5283
5383
5366
5397
5289
5362
5422
5540
5417
5423
5489
5401
5472
5563
5434
5484
5549
5546
5560
5404
5524
5511
5577
5543
5523
5453
5600
5620
5658
5614
5582
5590
5609
5573
5591
5702
5683
5600
5658
5636
5621
5668
5659
5721
5779
5751
5698
5577
5709
5715
5687
5674
5640
5699
5788
5786
5850
5733
5704
5803
5746
5722
5804
5820
5760
5849
5914
5911
5960
5872
5837
5897
5937
6049
5945
5891
6096
6091
6159
6121
5938
6014
6102
5962
5916
5867
5816
5824
5919
5870
5717
5616
5650
5757
5666
5729
5882
6368
7347
8641
8914
8216
7078
6035
5670
5492
5456
5527
5495
5463
5463
5477
5409
5657
5549
5492
5560
5418
5526
5436
5433
5514
5477
5628
5507
5566
5656
5621
5544
5536
5568
5568
5515
5602
5593
5573
5509
5643
5501
5623
5655
5511
5618
5665
5615
5598
5738
5800
5660
5726
5687
5596
5761
5657
5795
5739
5968
5958
5910
5811
5870
5879
5997
5886
6030
6074
5826
6095
6084
5821
5392
5090
5091
5186
5446
5855
6655
7845
10367
11953
10319
6588
4472
4532
6195
9743
13697
14382
9941
4805
2742
2307
2143
2189
2111
2070
2111
2085
2120
2141
2172
2117
2098
2015
2014
2081
2090
2084
2041
2047
2129
2073
2124
2087
2059
2120
2097
2075
2134
2122
2109
2095
2050
2088
2085
2093
2152
2082
2114
2174
2163
2211
2164
2211
2135
2137
2154
2161
2094
2127
2111
2143
2100
2048
2080
2161
2131
2159
2140
2200
2132
2125
2138
2134
2168
2151
2167
2170
2229
2215
2226
2278
2240
2224
2229
2342
2225
2250
2251
2256
2262
2257
2245
2250
2169
2216
2236
2224
2321
2335
2292
2274
2257
2217
2270
2362
2278
2234
2308
2401
2332
2354
2338
2369
2321
2307
2225
2245
2352
2359
2313
2271
2389
2397
2423
2421
2366
2396
2380
2430
2458
2400
2382
2346
2429
2413
2433
2430
2437
2405
2490
2492
2473
2414
2467
2428
2450
2388
2434
2489
2351
2274
2168
2195
2109
1995
1948
1956
1911
1967
2051
2171
2191
2213
2302
2605
3631
5129
7381
7125
3893
1683
1266
1254
1196
1193
1127
1141
1163
1164
1141
1156
1187
1141
1127
1149
1192
1155
1170
1181
1194
1143
1161
1165
1236
1187
1275
1216
1219
1213
1223
1187
1255
1203
1227
1208
1171
1158
1140
1210
1147
1135
1194
1185
1212
1201
1177
1213
1260
1216
1284
1255
1248
1256
1347
1435
1378
1264
1224
1171
1158
1159
1162
1192
1134
1148
1119
1099
1158
1147
1126
1151
1177
1179
1190
1166
1181
1115
1151
1167
1138
1178
1179
1186
1132
1116
1175
1200
1157
1135
1189
1182
1192
1226
1165
1173
1215
1200
1204
1283
1246
1199
1149
1114
1163
1192
1115
1167
1153
1123
1156
1208
1235
1237
1252
1244
1215
1261
1392
1537
1473
1268
1125
1062
1084
1074
1114
1086
1072
1063
1049
1047
1068
1088
1054
1086
1057
1102
1118
1101
1075
1061
1074
1097
1096
1111
1113
1105
1099
1114
1077
1096
1092
1145
1173
1230
1276
1301
1260
1242
1167
1147
1118
1068
1065
1031
1021
1006
1036
1033
1045
1038
1030
1020
1078
1034
1035
1084
1096
1102
1033
1097
1043
1032
1077
1087
1086
1122
1142
1119
1121
1156
1168
1184
1147
1180
1205
1184
1194
1188
1225
1222
1280
1254
1152
1068
1036
983
888
821
770
791
775
775
677
644
632
655
652
606
552
587
590
640
600
601
600
588
613
586
625
605
569
629
619
582
596
598
690
623
706
656
695
659
624
620
626
602
624
642
726
780
844
825
641
542
487
583
587
596
842
1230
2074
2684
2657
1662
673
267
215
204
193
150
157
143
157
166
167
140
121
94
75
42
23
4
3
1
5
38.0316
S 2p/3
sh1
2023
6
9
15
19
22
0
9
Casa Info Follows
0
0
0
0
sh1.vms Dir:D:\Google Drive\1 Academic\0 Berkeley\0 Long\B30 XPS\20230609 march of the pafs\
   XPS     Spectrum    Lens Mode:Hybrid   Resolution:Pass energy 40    Iris(Aper):slot(Slot)
   Acqn. Time(s): 1028       Sweeps: 15       Anode:Mono(Al (Mono))(75 W)   Step(meV): 100.0
   Dwell Time(ms): 426        Charge Neutraliser :On   Acquired On :23/06/09 15:19:22
XPS
82
2
0
0
Mono(Al (Mono))
1486.69
75
1e+037
1e+037
6000
6000
1e+037
1e+037
FAT
40
1e+037
-4.46
0
1e+037
1e+037
1e+037
1e+037
S
2p
-1
Kinetic Energy
eV
1312.69
0.1
2
Intensity
d
Transmission
d
pulse counting
0.4255
15
0
1e+037
1e+037
1e+037
1
MFP Exponent
d
-0.7414
322
9348
16086
4.90669
4.92393
9938
4.90669
9922
4.9068
9918
4.90691
9833
4.90702
9899
4.90712
10033
4.90723
9922
4.90734
9868
4.90745
9833
4.90756
9936
4.90766
9772
4.90777
9673
4.90788
9949
4.90799
9788
4.90809
9881
4.9082
9709
4.90831
9811
4.90842
9771
4.90853
9759
4.90863
9869
4.90874
9782
4.90885
9826
4.90896
9801
4.90906
9803
4.90917
9784
4.90928
9876
4.90939
9996
4.9095
10082
4.9096
10186
4.90971
10308
4.90982
10404
4.90993
10446
4.91003
10597
4.91014
10762
4.91025
10785
4.91036
10798
4.91046
11002
4.91057
11189
4.91068
11038
4.91079
11087
4.9109
11038
4.911
11199
4.91111
11359
4.91122
11547
4.91133
11385
4.91143
11279
4.91154
11555
4.91165
11736
4.91176
11643
4.91187
11717
4.91197
11524
4.91208
11388
4.91219
11243
4.9123
10997
4.9124
10878
4.91251
10837
4.91262
10840
4.91273
10657
4.91284
10667
4.91294
10707
4.91305
10587
4.91316
10655
4.91327
10650
4.91337
10692
4.91348
10500
4.91359
10645
4.9137
10717
4.9138
10596
4.91391
10611
4.91402
10775
4.91413
10687
4.91424
10619
4.91434
10664
4.91445
10666
4.91456
10595
4.91467
10582
4.91477
10790
4.91488
10644
4.91499
10536
4.9151
10605
4.91521
10623
4.91531
10502
4.91542
10564
4.91553
10493
4.91564
10636
4.91574
10481
4.91585
10639
4.91596
10668
4.91607
10560
4.91617
10500
4.91628
10594
4.91639
10839
4.9165
10742
4.91661
10928
4.91671
11057
4.91682
11063
4.91693
11242
4.91704
11370
4.91714
11476
4.91725
11637
4.91736
11835
4.91747
11998
4.91758
12329
4.91768
12397
4.91779
12834
4.9179
13107
4.91801
13194
4.91811
13489
4.91822
13933
4.91833
14382
4.91844
14650
4.91855
14793
4.91865
15014
4.91876
15107
4.91887
15414
4.91898
15379
4.91908
15663
4.91919
15797
4.9193
15851
4.91941
15986
4.91951
16086
4.91962
16039
4.91973
15983
4.91984
15942
4.91995
15635
4.92005
15211
4.92016
14843
4.92027
14387
4.92038
13733
4.92048
13070
4.92059
12573
4.9207
12018
4.92081
11701
4.92092
11179
4.92102
10927
4.92113
10311
4.92124
9935
4.92135
9969
4.92145
9966
4.92156
9715
4.92167
9688
4.92178
9440
4.92189
9378
4.92199
9540
4.9221
9453
4.92221
9348
4.92232
9380
4.92242
9507
4.92253
9369
4.92264
9576
4.92275
9459
4.92285
9414
4.92296
9436
4.92307
9422
4.92318
9393
4.92329
9530
4.92339
9509
4.9235
9425
4.92361
9515
4.92372
9505
4.92382
9459
4.92393
S 2s/4
sh1
2023
6
9
15
41
57
0
9
Casa Info Follows
0
0
0
0
sh1.vms Dir:D:\Google Drive\1 Academic\0 Berkeley\0 Long\B30 XPS\20230609 march of the pafs\
   XPS     Spectrum    Lens Mode:Hybrid   Resolution:Pass energy 40    Iris(Aper):slot(Slot)
   Acqn. Time(s): 601        Sweeps: 15       Anode:Mono(Al (Mono))(75 W)   Step(meV): 100.0
   Dwell Time(ms): 199        Charge Neutraliser :On   Acquired On :23/06/09 15:41:57
XPS
82
2
0
0
Mono(Al (Mono))
1486.69
75
1e+037
1e+037
6000
6000
1e+037
1e+037
FAT
40
1e+037
-4.46
0
1e+037
1e+037
1e+037
1e+037
S
2s
-1
Kinetic Energy
eV
1248.69
0.1
2
Intensity
d
Transmission
d
pulse counting
0.1993
15
0
1e+037
1e+037
1e+037
1
MFP Exponent
d
-0.7414
402
5068
7353
4.7976
4.83482
5368
4.7976
5430
4.79778
5387
4.79797
5275
4.79816
5338
4.79834
5376
4.79853
5320
4.79872
5300
4.7989
5247
4.79909
5443
4.79927
5406
4.79946
5391
4.79965
5226
4.79983
5288
4.80002
5456
4.8002
5363
4.80039
5293
4.80058
5309
4.80076
5395
4.80095
5344
4.80113
5325
4.80132
5471
4.80151
5380
4.80169
5408
4.80188
5398
4.80206
5379
4.80225
5434
4.80244
5397
4.80262
5503
4.80281
5402
4.803
5518
4.80318
5375
4.80337
5582
4.80355
5652
4.80374
5453
4.80393
5598
4.80411
5672
4.8043
5702
4.80448
5646
4.80467
5829
4.80486
5627
4.80504
5687
4.80523
5681
4.80542
5752
4.8056
5736
4.80579
5824
4.80597
5769
4.80616
5834
4.80635
5762
4.80653
5803
4.80672
5906
4.8069
5761
4.80709
5782
4.80728
5833
4.80746
5829
4.80765
5713
4.80783
5719
4.80802
5741
4.80821
5752
4.80839
5722
4.80858
5648
4.80876
5530
4.80895
5677
4.80914
5731
4.80932
5610
4.80951
5665
4.8097
5768
4.80988
5760
4.81007
5766
4.81025
5669
4.81044
5650
4.81063
5625
4.81081
5759
4.811
5770
4.81118
5640
4.81137
5541
4.81156
5685
4.81174
5664
4.81193
5681
4.81212
5698
4.8123
5623
4.81249
5621
4.81267
5571
4.81286
5628
4.81305
5717
4.81323
5700
4.81342
5747
4.8136
5895
4.81379
5783
4.81398
5771
4.81416
5822
4.81435
5832
4.81453
5869
4.81472
5960
4.81491
5842
4.81509
5944
4.81528
5902
4.81546
5930
4.81565
6057
4.81584
6120
4.81602
6111
4.81621
6242
4.8164
6216
4.81658
6152
4.81677
6300
4.81695
6438
4.81714
6538
4.81733
6622
4.81751
6543
4.8177
6658
4.81788
6754
4.81807
6842
4.81826
7038
4.81844
7049
4.81863
7065
4.81882
7091
4.819
7191
4.81919
7353
4.81937
7289
4.81956
7253
4.81975
7196
4.81993
7162
4.82012
7072
4.8203
6944
4.82049
6907
4.82068
6798
4.82086
6628
4.82105
6661
4.82123
6457
4.82142
6413
4.82161
6212
4.82179
6177
4.82198
6084
4.82217
6073
4.82235
5869
4.82254
5854
4.82272
5768
4.82291
5749
4.8231
5607
4.82328
5683
4.82347
5412
4.82365
5497
4.82384
5380
4.82403
5591
4.82421
5446
4.8244
5484
4.82458
5425
4.82477
5291
4.82496
5257
4.82514
5290
4.82533
5324
4.82552
5215
4.8257
5338
4.82589
5260
4.82607
5272
4.82626
5301
4.82645
5255
4.82663
5353
4.82682
5237
4.827
5242
4.82719
5222
4.82738
5218
4.82756
5268
4.82775
5314
4.82793
5282
4.82812
5270
4.82831
5207
4.82849
5164
4.82868
5278
4.82887
5137
4.82905
5157
4.82924
5130
4.82942
5341
4.82961
5163
4.8298
5159
4.82998
5194
4.83017
5235
4.83035
5235
4.83054
5177
4.83073
5122
4.83091
5295
4.8311
5267
4.83128
5215
4.83147
5165
4.83166
5226
4.83184
5212
4.83203
5152
4.83222
5208
4.8324
5238
4.83259
5208
4.83277
5231
4.83296
5307
4.83315
5201
4.83333
5146
4.83352
5144
4.8337
5254
4.83389
5166
4.83408
5215
4.83426
5068
4.83445
5127
4.83463
5185
4.83482
O 1s/5
sh1
2023
6
9
15
55
32
0
9
Casa Info Follows
0
0
0
0
sh1.vms Dir:D:\Google Drive\1 Academic\0 Berkeley\0 Long\B30 XPS\20230609 march of the pafs\
   XPS     Spectrum    Lens Mode:Hybrid   Resolution:Pass energy 40    Iris(Aper):slot(Slot)
   Acqn. Time(s): 701        Sweeps: 15       Anode:Mono(Al (Mono))(75 W)   Step(meV): 100.0
   Dwell Time(ms): 332        Charge Neutraliser :On   Acquired On :23/06/09 15:55:32
XPS
82
2
0
0
Mono(Al (Mono))
1486.69
75
1e+037
1e+037
6000
6000
1e+037
1e+037
FAT
40
1e+037
-4.46
0
1e+037
1e+037
1e+037
1e+037
O
1s
-1
Kinetic Energy
eV
947.69
0.1
2
Intensity
d
Transmission
d
pulse counting
0.3315
15
0
1e+037
1e+037
1e+037
1
MFP Exponent
d
-0.7414
282
41716
78629
4.55545
4.55665
44183
4.55545
44155
4.55546
44493
4.55547
44554
4.55548
44435
4.55548
44364
4.55549
44282
4.5555
44206
4.55551
43964
4.55552
44007
4.55553
43621
4.55554
43507
4.55554
43772
4.55555
43634
4.55556
43846
4.55557
43734
4.55558
43780
4.55559
43745
4.5556
43621
4.5556
43733
4.55561
43542
4.55562
43412
4.55563
43558
4.55564
43656
4.55565
43733
4.55566
43431
4.55566
43371
4.55567
43775
4.55568
43694
4.55569
43623
4.5557
43806
4.55571
43640
4.55572
43573
4.55572
43473
4.55573
43537
4.55574
43452
4.55575
43549
4.55576
43675
4.55577
43762
4.55577
43672
4.55578
44040
4.55579
44139
4.5558
44304
4.55581
44173
4.55582
44759
4.55583
44638
4.55583
44978
4.55584
45769
4.55585
46546
4.55586
47128
4.55587
47766
4.55588
48382
4.55589
48971
4.55589
50057
4.5559
51268
4.55591
52544
4.55592
54395
4.55593
56465
4.55594
58517
4.55595
60941
4.55595
63482
4.55596
65865
4.55597
68090
4.55598
70993
4.55599
73587
4.556
74943
4.55601
76835
4.55601
77834
4.55602
78249
4.55603
78629
4.55604
78173
4.55605
77975
4.55606
76438
4.55607
75095
4.55607
73578
4.55608
72333
4.55609
71426
4.5561
70280
4.55611
69453
4.55612
69660
4.55612
69267
4.55613
69342
4.55614
69218
4.55615
69309
4.55616
69495
4.55617
69384
4.55618
69553
4.55618
68823
4.55619
68342
4.5562
67131
4.55621
65496
4.55622
63698
4.55623
61644
4.55624
59150
4.55624
56836
4.55625
54904
4.55626
53133
4.55627
51135
4.55628
49314
4.55629
47979
4.5563
47215
4.5563
46131
4.55631
45462
4.55632
44915
4.55633
44233
4.55634
43767
4.55635
43391
4.55636
43353
4.55636
42961
4.55637
43012
4.55638
42648
4.55639
42648
4.5564
42615
4.55641
42829
4.55642
42414
4.55642
42323
4.55643
42109
4.55644
42196
4.55645
42266
4.55646
42197
4.55647
42129
4.55647
42093
4.55648
42146
4.55649
42071
4.5565
41935
4.55651
42043
4.55652
42148
4.55653
41919
4.55653
41716
4.55654
42137
4.55655
41957
4.55656
41775
4.55657
41810
4.55658
42190
4.55659
42344
4.55659
42373
4.5566
42533
4.55661
42636
4.55662
42586
4.55663
42694
4.55664
42605
4.55665
C 1s/6
sh1
2023
6
9
16
11
44
0
9
Casa Info Follows
0
0
0
0
sh1.vms Dir:D:\Google Drive\1 Academic\0 Berkeley\0 Long\B30 XPS\20230609 march of the pafs\
   XPS     Spectrum    Lens Mode:Hybrid   Resolution:Pass energy 40    Iris(Aper):slot(Slot)
   Acqn. Time(s): 444        Sweeps: 10       Anode:Mono(Al (Mono))(75 W)   Step(meV): 100.0
   Dwell Time(ms): 260        Charge Neutraliser :On   Acquired On :23/06/09 16:11:44
XPS
82
2
0
0
Mono(Al (Mono))
1486.69
75
1e+037
1e+037
6000
6000
1e+037
1e+037
FAT
40
1e+037
-4.46
0
1e+037
1e+037
1e+037
1e+037
C
1s
-1
Kinetic Energy
eV
1191.69
0.1
2
Intensity
d
Transmission
d
pulse counting
0.2597
10
0
1e+037
1e+037
1e+037
1
MFP Exponent
d
-0.7414
342
4597
51327
4.65677
4.70066
8065
4.65677
8225
4.65703
8148
4.65729
8271
4.65754
8051
4.6578
8153
4.65806
8028
4.65832
7964
4.65858
8072
4.65884
8032
4.65909
8128
4.65935
8043
4.65961
8011
4.65987
8034
4.66013
8031
4.66038
7983
4.66064
8211
4.6609
8106
4.66116
7935
4.66142
8080
4.66167
8029
4.66193
8051
4.66219
7985
4.66245
8000
4.66271
8107
4.66297
7947
4.66322
8003
4.66348
7982
4.66374
8061
4.664
8076
4.66426
8180
4.66452
8299
4.66477
8228
4.66503
8149
4.66529
8317
4.66555
8290
4.66581
8316
4.66606
8453
4.66632
8515
4.66658
8725
4.66684
8691
4.6671
8761
4.66735
8767
4.66761
8711
4.66787
9001
4.66813
8986
4.66839
9154
4.66865
9288
4.6689
9311
4.66916
9368
4.66942
9439
4.66968
9429
4.66994
9706
4.67019
9789
4.67045
9933
4.67071
10090
4.67097
9975
4.67123
10018
4.67149
10022
4.67174
9879
4.672
9720
4.67226
9469
4.67252
9248
4.67278
9003
4.67303
9129
4.67329
9049
4.67355
8948
4.67381
8626
4.67407
8517
4.67432
8399
4.67458
8261
4.67484
8232
4.6751
8157
4.67536
7889
4.67562
7888
4.67587
7890
4.67613
7936
4.67639
8115
4.67665
8053
4.67691
8033
4.67717
8008
4.67742
8230
4.67768
8054
4.67794
8294
4.6782
8518
4.67846
8656
4.67871
8878
4.67897
9103
4.67923
9534
4.67949
9908
4.67975
10336
4.68001
11031
4.68026
11459
4.68052
12210
4.68078
12571
4.68104
13140
4.6813
13664
4.68155
14310
4.68181
14780
4.68207
15269
4.68233
15812
4.68259
16488
4.68284
16902
4.6831
17724
4.68336
18550
4.68362
19717
4.68388
21123
4.68414
22589
4.68439
24124
4.68465
26002
4.68491
28277
4.68517
30776
4.68543
33286
4.68568
35836
4.68594
38418
4.6862
41074
4.68646
43771
4.68672
46569
4.68698
48689
4.68723
50227
4.68749
51227
4.68775
51327
4.68801
50257
4.68827
48827
4.68852
46226
4.68878
42904
4.68904
38919
4.6893
34427
4.68956
30033
4.68982
25821
4.69007
21827
4.69033
18061
4.69059
15048
4.69085
12505
4.69111
10552
4.69136
9005
4.69162
7786
4.69188
7014
4.69214
6191
4.6924
5943
4.69266
5627
4.69291
5536
4.69317
5328
4.69343
5048
4.69369
5025
4.69395
4977
4.6942
4888
4.69446
4818
4.69472
4826
4.69498
4818
4.69524
4789
4.69549
4796
4.69575
4808
4.69601
4896
4.69627
4752
4.69653
4710
4.69679
4820
4.69704
4740
4.6973
4698
4.69756
4597
4.69782
4715
4.69808
4724
4.69833
4785
4.69859
4657
4.69885
4704
4.69911
4675
4.69937
4668
4.69963
4616
4.69988
4765
4.70014
4665
4.7004
4627
4.70066
O KLL/7
sh1
2023
6
9
16
21
51
0
9
Casa Info Follows
0
0
0
0
sh1.vms Dir:D:\Google Drive\1 Academic\0 Berkeley\0 Long\B30 XPS\20230609 march of the pafs\
   XPS     Spectrum    Lens Mode:Hybrid   Resolution:Pass energy 40    Iris(Aper):slot(Slot)
   Acqn. Time(s): 810        Sweeps: 10       Anode:Mono(Al (Mono))(75 W)   Step(meV): 1000.0
   Dwell Time(ms): 988        Charge Neutraliser :On   Acquired On :23/06/09 16:21:51
XPS
82
2
0
0
Mono(Al (Mono))
1486.69
75
1e+037
1e+037
6000
6000
1e+037
1e+037
FAT
40
1e+037
-4.46
0
1e+037
1e+037
1e+037
1e+037
O
KLL
-1
Kinetic Energy
eV
450
1
2
Intensity
d
Transmission
d
pulse counting
0.9877
10
0
1e+037
1e+037
1e+037
1
MFP Exponent
d
-0.7414
164
93681
112052
4.5464
4.69339
99178
4.69339
99654
4.69041
99312
4.68742
98775
4.68444
98875
4.68145
99251
4.67847
99581
4.67549
99737
4.6725
100039
4.66952
99545
4.66653
99734
4.66366
100049
4.66192
100399
4.66018
100593
4.65844
100616
4.6567
100844
4.65496
100765
4.65322
101151
4.65148
101065
4.64974
100924
4.648
101197
4.64626
101696
4.64452
101256
4.64278
101723
4.64104
101851
4.6393
102024
4.63756
102210
4.63582
101768
4.63408
101791
4.63234
101693
4.6306
101740
4.62886
101810
4.62712
102267
4.62539
103013
4.62365
103044
4.62191
103867
4.62017
104576
4.61843
104596
4.61669
104841
4.61495
105069
4.61321
104984
4.61147
104825
4.60973
104249
4.60799
104433
4.60625
103887
4.60451
103187
4.60277
102690
4.60103
102401
4.59929
102057
4.59755
101728
4.59581
101936
4.59407
102106
4.59233
101800
4.59059
101674
4.58885
102616
4.58711
103739
4.58537
104874
4.58363
105983
4.58189
107419
4.58015
109859
4.57841
111288
4.5767
112052
4.57526
111478
4.57382
109786
4.57237
107440
4.57093
105494
4.56949
103535
4.56804
101349
4.5666
99493
4.56516
97657
4.56371
95903
4.56227
95373
4.56083
94533
4.55938
94110
4.55794
93681
4.5565
93903
4.55506
93801
4.55361
93821
4.55217
94235
4.55073
94157
4.54928
94371
4.54784
93906
4.5464
In 3d/8
sh1
2023
6
9
16
37
7
0
9
Casa Info Follows
0
0
0
0
sh1.vms Dir:D:\Google Drive\1 Academic\0 Berkeley\0 Long\B30 XPS\20230609 march of the pafs\
   XPS     Spectrum    Lens Mode:Hybrid   Resolution:Pass energy 40    Iris(Aper):slot(Slot)
   Acqn. Time(s): 600        Sweeps: 10       Anode:Mono(Al (Mono))(75 W)   Step(meV): 100.0
   Dwell Time(ms): 298        Charge Neutraliser :On   Acquired On :23/06/09 16:37:07
XPS
82
2
0
0
Mono(Al (Mono))
1486.69
75
1e+037
1e+037
6000
6000
1e+037
1e+037
FAT
40
1e+037
-4.46
0
1e+037
1e+037
1e+037
1e+037
In
3d
-1
Kinetic Energy
eV
1027.69
0.1
2
Intensity
d
Transmission
d
pulse counting
0.2985
10
0
1e+037
1e+037
1e+037
1
MFP Exponent
d
-0.7414
402
10456
89791
4.60709
4.62395
23557
4.60709
23567
4.60717
23552
4.60726
23748
4.60734
23617
4.60743
23675
4.60751
23905
4.60759
24055
4.60768
24133
4.60776
24107
4.60785
24228
4.60793
24098
4.60802
24261
4.6081
24410
4.60818
24640
4.60827
24670
4.60835
24757
4.60844
24708
4.60852
25175
4.60861
25211
4.60869
25503
4.60878
25447
4.60886
25876
4.60894
25796
4.60903
26191
4.60911
26460
4.6092
26655
4.60928
27138
4.60937
27697
4.60945
27777
4.60953
27998
4.60962
28443
4.6097
28515
4.60979
28724
4.60987
28992
4.60996
29008
4.61004
29018
4.61012
28789
4.61021
28491
4.61029
28286
4.61038
27641
4.61046
27220
4.61055
27392
4.61063
27089
4.61071
27466
4.6108
27998
4.61088
28953
4.61097
30118
4.61105
31857
4.61114
33510
4.61122
35180
4.6113
38010
4.61139
40810
4.61147
43522
4.61156
46407
4.61164
49675
4.61173
52825
4.61181
55265
4.6119
57540
4.61198
60033
4.61206
61435
4.61215
62989
4.61223
63706
4.61232
64229
4.6124
64722
4.61249
64412
4.61257
64210
4.61265
63741
4.61274
62788
4.61282
62068
4.61291
61885
4.61299
61813
4.61308
62662
4.61316
64494
4.61324
67025
4.61333
68962
4.61341
68986
4.6135
66236
4.61358
59357
4.61367
50745
4.61375
42016
4.61383
34850
4.61392
29182
4.614
25693
4.61409
23552
4.61417
22215
4.61426
21079
4.61434
19892
4.61442
19016
4.61451
18485
4.61459
17958
4.61468
17849
4.61476
17372
4.61485
17200
4.61493
17032
4.61501
16949
4.6151
16793
4.61518
16561
4.61527
16529
4.61535
16237
4.61544
16415
4.61552
16369
4.6156
16096
4.61569
16163
4.61577
16216
4.61586
15992
4.61594
16126
4.61603
16392
4.61611
16237
4.6162
16477
4.61628
16792
4.61636
16974
4.61645
17227
4.61653
17629
4.61662
18008
4.6167
18405
4.61679
19059
4.61687
19606
4.61695
20439
4.61704
21720
4.61712
22857
4.61721
24764
4.61729
26263
4.61738
28637
4.61746
31393
4.61754
34593
4.61763
38481
4.61771
42311
4.6178
46729
4.61788
51218
4.61797
55793
4.61805
60356
4.61813
64530
4.61822
68559
4.6183
71909
4.61839
74852
4.61847
77126
4.61856
78631
4.61864
79607
4.61872
80856
4.61881
80612
4.61889
80761
4.61898
79584
4.61906
79088
4.61915
77774
4.61923
76836
4.61932
76689
4.6194
77534
4.61948
80107
4.61957
83751
4.61965
87351
4.61974
89791
4.61982
87524
4.6199
80701
4.61999
69657
4.62007
56858
4.62016
44787
4.62024
35061
4.62033
28269
4.62041
24149
4.6205
21292
4.62058
19348
4.62066
18204
4.62075
16833
4.62083
15830
4.62092
15173
4.621
14646
4.62109
14096
4.62117
13598
4.62125
13344
4.62134
13069
4.62142
12828
4.62151
12613
4.62159
12317
4.62168
12148
4.62176
12019
4.62184
11744
4.62193
11567
4.62201
11492
4.6221
11437
4.62218
11425
4.62227
11241
4.62235
11244
4.62243
11076
4.62252
11082
4.6226
11019
4.62269
11089
4.62277
11059
4.62286
10791
4.62294
10861
4.62302
10896
4.62311
10819
4.62319
10704
4.62328
10678
4.62336
10557
4.62345
10621
4.62353
10456
4.62362
10701
4.6237
10477
4.62378
10624
4.62387
10637
4.62395
survey/9
sh1
2023
6
9
16
50
10
0
9
Casa Info Follows
0
0
0
0
sh1.vms Dir:D:\Google Drive\1 Academic\0 Berkeley\0 Long\B30 XPS\20230609 march of the pafs\
   XPS     Spectrum    Lens Mode:Hybrid   Resolution:Pass energy 160   Iris(Aper):slot(Slot)
   Acqn. Time(s): 121        Sweeps: 1        Anode:Mono(Al (Mono))(75 W)   Step(meV): 1000.0
   Dwell Time(ms): 100        Charge Neutraliser :On   Acquired On :23/06/09 16:50:10
XPS
82
2
0
0
Mono(Al (Mono))
1486.69
75
1e+037
1e+037
6000
6000
1e+037
1e+037
FAT
160
1e+037
-4.46
0
1e+037
1e+037
1e+037
1e+037
Wide
None
-1
Kinetic Energy
eV
286.69
1
2
Intensity
d
Transmission
d
pulse counting
0.1
1
0
1e+037
1e+037
1e+037
1
MFP Exponent
d
-0.7414
1
27.6167
9427
9436
9445
9376
9554
9629
9418
9579
9655
9627
9522
9518
9404
9381
9269
9228
9232
9432
9310
9131
9262
9209
9246
9393
9258
9260
9244
9315
9417
9458
9323
9316
9434
9388
9389
9490
9304
9440
9469
9442
9569
9466
9457
9531
9474
9320
9347
9387
9415
9308
9373
9490
9631
9436
9479
9336
9384
9192
9095
9092
9059
8997
9146
9035
8946
9020
8800
8563
8715
8712
8625
8730
8684
8660
8758
8681
8824
8765
8825
8800
8723
8798
8836
8925
8863
8856
8829
8839
8967
9104
8983
9005
8776
9001
9085
8993
8883
8977
8932
9020
8822
8692
8930
8671
8822
8801
9000
8943
9072
9373
9462
9929
10392
10417
10332
10250
9884
9615
9669
9592
9330
9119
8631
8325
8270
7880
7766
7605
7604
7432
7435
7482
7533
7601
7428
7449
7381
7338
7515
7470
7447
7313
7383
7389
7343
7338
7350
7458
7381
7543
7603
7490
7379
7377
7418
7421
7507
7580
7559
7536
7612
7576
7488
7494
7508
7508
7523
7575
7710
7771
7714
7592
7621
7649
7731
7667
7657
7811
7787
7886
7884
7640
7730
7819
7805
7876
7851
7810
7849
7905
8047
8015
7871
7890
7987
8036
7839
7894
7936
8044
8201
8157
8079
8132
8221
8152
8124
8127
8058
8100
8046
7994
8067
7966
7952
7893
7969
8041
8084
8208
8101
8342
8565
8688
8668
8721
8675
8767
8467
8221
8060
8026
7945
7771
7638
7604
7414
7431
7542
7521
7478
7455
7423
7354
7440
7464
7340
7531
7552
7575
7548
7472
7564
7556
7556
7458
7467
7511
7540
7514
7524
7598
7499
7627
7463
7420
7367
7546
7711
7600
7699
7719
7633
7626
7572
7619
7696
7684
7834
7741
7708
7656
7638
7684
7584
7732
7693
7716
7676
7708
7751
7728
7594
7655
7518
7773
7744
7737
7828
7877
7802
7751
7877
7851
7903
7690
7848
7869
7966
7908
7651
7642
7778
7837
7885
7939
7956
7777
7958
7875
7900
8042
7824
7931
7937
7875
7848
7871
7948
8005
7920
8046
8151
8116
8135
8059
7976
8018
8062
7990
7891
7955
8197
8181
8136
8123
8174
8089
8119
8233
8242
8165
8064
8099
8112
8154
8038
8179
8202
8154
8108
8232
8367
8294
8291
8358
8262
8408
8468
8335
8438
8532
8602
8618
8571
8516
8384
8400
8269
8169
8281
8135
8115
8200
8095
8097
8163
8138
8083
8025
8078
8194
8039
8039
8028
8085
8034
8189
8158
8011
8019
8044
8232
8178
8105
8268
8161
8146
8148
8141
8130
8251
8371
8208
8192
8230
8210
8126
8209
8118
8018
8202
8318
8324
8287
8336
8243
8351
8267
8257
8313
8314
8378
8454
8263
8347
8305
8321
8316
8526
8511
8394
8395
8389
8290
8462
8513
8600
8329
8414
8420
8428
8540
8523
8451
8516
8493
8423
8395
8486
8550
8665
8463
8453
8600
8513
8674
8438
8567
8661
8658
8653
8719
8709
8634
8698
8653
8720
8806
8748
8550
8627
8762
8863
8845
8682
8673
8778
8664
8602
8673
8586
8797
9167
9447
10132
10515
10488
9841
9208
8680
8541
8418
8385
8201
8301
8322
8338
8300
8292
8379
8373
8449
8408
8492
8452
8301
8371
8207
8190
8282
8457
8342
8311
8167
7983
8004
7951
8096
8352
8553
8900
10051
11012
11571
11355
10461
9317
8469
7808
7601
7401
7274
7169
7143
7128
7032
7084
7044
7180
7120
7081
7008
6890
6961
6938
7078
6928
7065
7026
7136
6979
6980
6974
7004
6933
7028
7033
7143
7167
6980
6958
7007
7153
7251
7173
7254
7157
7190
7153
7265
7138
7165
7081
7197
7175
7223
7283
7315
7289
7223
7202
7232
7314
7311
7203
7257
7271
7252
7285
7398
7313
7305
7320
7278
7421
7402
7426
7468
7344
7429
7497
7496
7498
7581
7692
7349
7396
7554
7503
7470
7462
7468
7684
7484
7447
7518
7550
7507
7479
7563
7562
7662
7650
7594
7652
7638
7620
7594
7680
7690
7655
7817
7874
7840
7791
7927
7692
7746
7988
7936
7928
7811
7678
7617
7599
7633
7548
7649
7377
7464
7371
7482
7540
7634
7756
8180
9574
11383
11705
10873
9317
7915
7367
7261
7186
7054
7235
7152
6983
7067
7126
7207
7149
7099
7011
7069
7258
7351
7227
7090
7093
7108
7187
7180
7263
7269
7087
7273
7248
7250
7304
7215
7361
7307
7333
7273
7365
7419
7412
7374
7287
7245
7371
7359
7411
7493
7297
7372
7423
7451
7553
7535
7665
7637
7710
7636
7538
7592
7641
7710
7744
7773
7766
7791
7855
8013
8171
7653
7108
6796
6735
6849
7204
7713
8214
9945
13409
15800
14061
8932
5690
5634
7454
12071
17699
19175
13673
6588
3676
3191
3077
2942
2828
2774
2778
2782
2787
2835
2875
2759
2751
2784
2739
2726
2853
2750
2790
2749
2774
2774
2913
2797
2784
2782
2904
2752
2838
2879
2791
2800
2871
2796
2902
2836
2823
2815
2806
2888
2847
3032
3063
2955
2984
2887
2950
2934
2868
2904
2909
2944
2952
2911
2994
2976
2961
2974
2905
2922
2928
2878
2945
2959
2893
3020
3011
2942
2986
3007
2965
2987
2987
3000
3055
2990
2981
3071
3054
3045
3066
3067
3025
3017
3032
3042
3070
3101
3092
3127
3062
3032
3068
3071
3064
3023
3114
3145
3168
3177
3145
3130
3141
3206
3221
3242
3206
3139
3132
3126
3266
3258
3270
3134
3179
3208
3229
3189
3243
3262
3143
3268
3214
3257
3299
3264
3296
3292
3330
3293
3312
3302
3299
3307
3395
3443
3404
3267
3317
3306
3207
3118
3017
2909
2822
2815
2737
2642
2621
2636
2740
2947
3091
2966
2955
3364
4885
7403
10592
9870
4939
2166
1614
1563
1593
1524
1567
1571
1527
1507
1560
1549
1477
1526
1518
1514
1531
1526
1575
1559
1594
1584
1548
1576
1570
1640
1625
1592
1589
1533
1515
1535
1582
1578
1550
1558
1485
1544
1541
1595
1545
1565
1540
1507
1531
1558
1575
1573
1602
1663
1680
1618
1689
1734
1768
1886
1901
1744
1611
1570
1478
1508
1465
1422
1468
1487
1486
1533
1514
1466
1521
1428
1511
1476
1481
1477
1493
1541
1556
1562
1536
1545
1526
1529
1536
1523
1561
1526
1573
1528
1590
1633
1652
1570
1547
1541
1628
1633
1676
1662
1626
1555
1526
1518
1552
1506
1495
1461
1462
1393
1515
1586
1649
1603
1634
1608
1638
1711
1841
2021
1931
1646
1444
1409
1356
1402
1376
1451
1428
1393
1403
1444
1405
1420
1414
1392
1448
1454
1446
1454
1438
1474
1418
1446
1407
1478
1414
1487
1516
1426
1420
1448
1464
1537
1507
1618
1585
1671
1698
1743
1592
1410
1386
1385
1378
1405
1333
1380
1362
1390
1332
1357
1379
1358
1377
1398
1375
1380
1401
1446
1488
1469
1491
1427
1446
1427
1476
1478
1457
1514
1534
1551
1506
1559
1535
1567
1575
1557
1557
1574
1571
1560
1575
1497
1519
1447
1390
1280
1137
1104
1082
1025
1085
994
861
859
830
854
828
841
798
814
757
783
798
782
775
751
788
790
787
811
799
778
825
854
866
794
860
968
905
924
899
875
845
809
824
771
836
849
932
978
1095
1022
858
767
724
691
731
808
993
1561
2635
3652
3649
2288
911
414
289
243
241
213
195
219
229
239
238
207
170
114
80
54
26
7
4
3
1
38.0316
survey/2
sh2
2023
6
9
16
53
2
0
9
Casa Info Follows
0
0
0
0
sh2.vms Dir:D:\Google Drive\1 Academic\0 Berkeley\0 Long\B30 XPS\20230609 march of the pafs\
   XPS     Spectrum    Lens Mode:Hybrid   Resolution:Pass energy 160   Iris(Aper):slot(Slot)
   Acqn. Time(s): 121        Sweeps: 1        Anode:Mono(Al (Mono))(75 W)   Step(meV): 1000.0
   Dwell Time(ms): 100        Charge Neutraliser :On   Acquired On :23/06/09 16:53:02
XPS
83
2
1
0
Mono(Al (Mono))
1486.69
75
1e+037
1e+037
6000
6000
1e+037
1e+037
FAT
160
1e+037
-4.46
0
1e+037
1e+037
1e+037
1e+037
Wide
None
-1
Kinetic Energy
eV
286.69
1
2
Intensity
d
Transmission
d
pulse counting
0.1
1
0
1e+037
1e+037
1e+037
1
MFP Exponent
d
-0.7414
1
27.6167
7657
7622
7860
7811
7628
7643
7873
7991
7930
7892
7882
7729
7866
7708
7594
7511
7682
7604
7676
7613
7495
7684
7520
7526
7622
7727
7595
7707
7697
7640
7626
7804
7587
7635
7727
7741
7696
7641
7655
7811
7656
7801
7767
7793
7658
7730
7688
7741
7603
7671
7732
7728
7621
7561
7630
7542
7542
7590
7508
7530
7388
7472
7451
7490
7379
7353
7239
7158
7142
6987
7245
7127
7107
7271
7196
7173
7254
7202
7144
7115
7231
7206
7147
7143
7246
7214
7238
7315
7334
7311
7309
7385
7345
7363
7286
7346
7272
7238
7241
7287
7220
7273
7274
7209
7364
7268
7169
7235
7464
7549
7767
8086
8171
8474
8302
8185
8104
8094
7912
7778
7584
7450
7165
6909
6742
6574
6447
6212
6153
6246
6299
6180
6106
6197
6209
6252
6398
6202
6190
6230
6198
6128
6064
6203
6232
6042
6190
6198
6188
6244
6273
6197
6258
6183
6268
6347
6295
6279
6270
6291
6299
6351
6278
6291
6221
6400
6304
6301
6309
6300
6345
6362
6424
6359
6306
6282
6378
6402
6487
6400
6464
6571
6468
6383
6414
6544
6509
6569
6599
6628
6675
6650
6634
6603
6713
6570
6461
6554
6718
6718
6810
6791
6896
6763
6720
6834
6899
6820
6873
6776
6744
6555
6689
6580
6584
6666
6659
6645
6675
6838
6962
6987
6949
7133
7464
7360
7211
7172
7043
6804
6762
6607
6469
6391
6138
6225
6283
6264
6185
6232
6193
6128
6125
6156
6205
6189
6146
6177
6212
6143
6240
6172
6164
6224
6156
6148
6220
6179
6270
6059
6203
6204
6351
6273
6346
6391
6308
6313
6288
6303
6283
6237
6377
6306
6479
6376
6374
6210
6259
6303
6317
6380
6317
6402
6310
6390
6441
6406
6372
6349
6397
6438
6282
6475
6385
6351
6525
6543
6434
6396
6524
6389
6452
6413
6564
6437
6464
6493
6437
6391
6458
6469
6595
6520
6452
6489
6517
6516
6584
6543
6635
6650
6558
6530
6522
6571
6553
6619
6525
6577
6596
6595
6518
6479
6561
6627
6729
6763
6640
6558
6596
6672
6773
6824
6829
6790
6647
6597
6705
6799
6738
6676
6758
6855
6805
6728
6833
6812
6885
6845
6826
6856
6796
6834
6803
6720
6763
6945
6907
6931
6864
6991
6939
6993
7006
7014
6995
7000
6809
6780
6853
6854
6756
6824
6740
6803
6712
6747
6682
6756
6644
6641
6692
6810
6721
6801
6743
6791
6656
6757
6800
6718
6719
6727
6704
6779
6798
6810
6762
6799
6884
6754
6827
6826
6789
6745
6857
6724
6695
6768
6885
6947
6989
6934
6951
6897
6815
6862
6950
6935
6971
7004
7002
6938
6936
6809
6879
6938
7064
7059
6932
7005
6980
7026
7018
7088
7030
7089
6920
6998
7115
7145
7058
6999
7132
7085
7000
6923
7016
7065
7075
7103
7189
7247
7089
7006
7151
7237
7191
7270
7158
7210
7255
7187
7174
7223
7158
7132
7176
7133
7151
7096
7263
7346
7273
7227
7287
7294
7225
7063
7159
7232
7275
7620
7655
8137
8574
8637
7990
7758
7313
7028
7077
6948
6995
6897
6994
6983
6992
7011
7012
7010
7031
6822
7089
7119
6901
6953
6831
6967
7007
6868
7036
7037
6989
6894
6758
6789
6789
6824
7054
7426
8051
8918
9354
9337
8563
7659
7019
6699
6432
6330
6110
6136
6138
6118
6058
6125
6019
6039
5981
6054
5896
5967
6021
6001
5979
5965
6008
6098
6007
5942
6021
6006
6079
6014
6026
6099
6014
6083
6103
6169
6129
6073
6027
6028
6055
6054
6119
6050
6156
6140
6304
6301
6182
6249
6229
6264
6266
6229
6203
6211
6143
6160
6061
6231
6272
6272
6306
6237
6260
6213
6232
6172
6254
6373
6292
6329
6286
6415
6247
6364
6391
6411
6445
6385
6290
6485
6378
6444
6423
6483
6505
6517
6460
6373
6419
6475
6335
6360
6402
6437
6516
6423
6566
6493
6457
6477
6576
6595
6625
6681
6555
6635
6629
6781
6879
6704
6816
6670
6637
6609
6615
6559
6496
6476
6474
6375
6396
6404
6481
6445
6228
6433
6490
6565
6963
8045
9511
9878
9319
8070
6800
6158
6124
6147
5954
6008
6089
6223
6260
6060
6174
6175
6098
5942
5993
6042
6166
6145
6204
6222
6207
6135
6219
6219
6131
6006
6146
6211
6214
6139
6114
6194
6044
6082
6170
6176
6193
6166
6284
6242
6054
6264
6251
6334
6394
6357
6237
6215
6291
6254
6342
6401
6488
6542
6538
6395
6286
6460
6493
6593
6590
6610
6470
6514
6607
6761
6556
6111
5800
5639
5732
6089
6337
7022
7950
10381
12264
11840
7934
5256
5036
6209
9106
13242
15094
11696
5993
3485
3059
2927
2933
2850
2693
2740
2783
2825
2802
2801
2816
2831
2809
2777
2862
2912
2870
2815
2827
2845
2872
2892
2812
2859
2910
2857
2808
2814
2848
2792
2764
2801
2905
2970
2864
2941
2913
2923
2916
2927
3057
2944
2882
2907
2924
2872
2928
2914
2963
2919
2911
2877
2900
2901
2927
2922
2882
2914
2910
3046
3030
2993
2961
3046
3058
3030
2997
2981
3073
3004
2918
2957
3040
3104
3005
2988
3007
3041
3048
3005
2992
3136
3090
3117
3048
3083
3106
3118
3055
3097
3175
3118
3138
3119
3233
3207
3100
3099
3196
3121
3151
3218
3277
3140
3127
3215
3282
3268
3225
3247
3260
3289
3266
3246
3141
3230
3331
3293
3280
3254
3326
3325
3344
3240
3261
3231
3357
3300
3257
3353
3340
3360
3327
3462
3450
3366
3412
3399
3302
3080
2998
2911
2833
2618
2513
2593
2534
2397
2551
2664
2838
2999
2838
2821
3461
5098
8320
11890
9941
4530
1946
1425
1427
1364
1277
1307
1325
1262
1297
1320
1346
1273
1315
1357
1312
1290
1305
1242
1304
1291
1342
1379
1286
1310
1404
1352
1367
1373
1390
1303
1323
1360
1332
1301
1324
1295
1301
1360
1310
1288
1295
1311
1282
1300
1342
1340
1355
1396
1346
1441
1412
1428
1525
1672
1752
1647
1455
1325
1234
1236
1290
1198
1198
1234
1238
1209
1223
1253
1243
1231
1249
1283
1285
1248
1219
1270
1247
1251
1327
1261
1303
1280
1242
1179
1204
1251
1252
1306
1273
1277
1254
1337
1300
1266
1313
1226
1297
1323
1380
1345
1292
1238
1248
1194
1193
1180
1206
1171
1158
1082
1286
1285
1301
1291
1298
1302
1434
1712
1905
1741
1319
1079
1055
1075
1080
1068
1068
1082
1073
1066
1100
1127
1085
1093
1105
1091
1116
1090
1050
1065
1128
1075
1088
1077
1095
1079
1083
1117
1129
1099
1139
1149
1088
1135
1189
1267
1280
1333
1295
1163
1108
1078
1084
1065
1032
1031
1015
1053
1029
1028
1042
1028
995
1015
1027
1002
1009
1010
1063
1101
1062
1092
1105
1134
1088
1089
1084
1102
1092
1116
1126
1137
1169
1172
1173
1162
1202
1152
1182
1209
1157
1159
1164
1142
1077
1044
949
892
815
789
842
835
802
730
599
614
607
606
625
609
594
604
585
580
571
626
637
626
611
622
617
644
626
599
605
637
648
702
683
683
683
682
710
681
645
653
637
603
668
693
739
797
766
626
562
526
532
587
621
724
1131
1829
2514
2594
1794
781
364
280
247
223
202
178
181
183
185
187
182
131
99
87
48
29
8
2
1
2
38.0316
S 2p/3
sh2
2023
6
9
16
55
40
0
9
Casa Info Follows
0
0
0
0
sh2.vms Dir:D:\Google Drive\1 Academic\0 Berkeley\0 Long\B30 XPS\20230609 march of the pafs\
   XPS     Spectrum    Lens Mode:Hybrid   Resolution:Pass energy 40    Iris(Aper):slot(Slot)
   Acqn. Time(s): 1028       Sweeps: 15       Anode:Mono(Al (Mono))(75 W)   Step(meV): 100.0
   Dwell Time(ms): 426        Charge Neutraliser :On   Acquired On :23/06/09 16:55:40
XPS
83
2
1
0
Mono(Al (Mono))
1486.69
75
1e+037
1e+037
6000
6000
1e+037
1e+037
FAT
40
1e+037
-4.46
0
1e+037
1e+037
1e+037
1e+037
S
2p
-1
Kinetic Energy
eV
1312.69
0.1
2
Intensity
d
Transmission
d
pulse counting
0.4255
15
0
1e+037
1e+037
1e+037
1
MFP Exponent
d
-0.7414
322
7324
16443
4.90669
4.92393
8382
4.90669
8425
4.9068
8401
4.90691
8302
4.90702
8223
4.90712
8364
4.90723
8378
4.90734
8278
4.90745
8324
4.90756
8295
4.90766
8266
4.90777
8220
4.90788
8268
4.90799
8045
4.90809
8103
4.9082
8109
4.90831
8076
4.90842
8109
4.90853
8118
4.90863
8217
4.90874
8209
4.90885
8178
4.90896
8127
4.90906
8219
4.90917
8376
4.90928
8241
4.90939
8314
4.9095
8526
4.9096
8381
4.90971
8510
4.90982
8624
4.90993
8757
4.91003
8729
4.91014
8847
4.91025
8790
4.91036
8966
4.91046
9024
4.91057
8914
4.91068
9184
4.91079
9111
4.9109
9324
4.911
9338
4.91111
9401
4.91122
9411
4.91133
9583
4.91143
9626
4.91154
9645
4.91165
9650
4.91176
9694
4.91187
9737
4.91197
9572
4.91208
9476
4.91219
9357
4.9123
9379
4.9124
9263
4.91251
9307
4.91262
9139
4.91273
9128
4.91284
9071
4.91294
9046
4.91305
9091
4.91316
8994
4.91327
9128
4.91337
9116
4.91348
9172
4.91359
9164
4.9137
9199
4.9138
9084
4.91391
9104
4.91402
8922
4.91413
9159
4.91424
9095
4.91434
8983
4.91445
9045
4.91456
9091
4.91467
8942
4.91477
8940
4.91488
8849
4.91499
8862
4.9151
8899
4.91521
8762
4.91531
8792
4.91542
8769
4.91553
8720
4.91564
8904
4.91574
8818
4.91585
8715
4.91596
8780
4.91607
8883
4.91617
8884
4.91628
9052
4.91639
9244
4.9165
9292
4.91661
9453
4.91671
9548
4.91682
9826
4.91693
9950
4.91704
10174
4.91714
10484
4.91725
10847
4.91736
11152
4.91747
11434
4.91758
11858
4.91768
12217
4.91779
12633
4.9179
13053
4.91801
13538
4.91811
13758
4.91822
14127
4.91833
14450
4.91844
14871
4.91855
15323
4.91865
15583
4.91876
15930
4.91887
16163
4.91898
16137
4.91908
16368
4.91919
16321
4.9193
16443
4.91941
16272
4.91951
16086
4.91962
15975
4.91973
15289
4.91984
14820
4.91995
14280
4.92005
13650
4.92016
12869
4.92027
12256
4.92038
11711
[...]
5672
4.80504
5889
4.80523
5810
4.80542
5784
4.8056
5860
4.80579
5717
4.80597
5652
4.80616
5775
4.80635
5810
4.80653
5862
4.80672
5792
4.8069
5890
4.80709
5920
4.80728
5960
4.80746
5891
4.80765
6060
4.80783
6118
4.80802
6092
4.80821
5958
4.80839
6098
4.80858
6042
4.80876
6083
4.80895
6239
4.80914
6059
4.80932
6140
4.80951
6158
4.8097
6137
4.80988
6118
4.81007
6230
4.81025
6330
4.81044
6225
4.81063
6309
4.81081
6274
4.811
6147
4.81118
6264
4.81137
6320
4.81156
6252
4.81174
6180
4.81193
6333
4.81212
6176
4.8123
6168
4.81249
6169
4.81267
6218
4.81286
6146
4.81305
6189
4.81323
6115
4.81342
6200
4.8136
6143
4.81379
6127
4.81398
6172
4.81416
6169
4.81435
6119
4.81453
6196
4.81472
6037
4.81491
6006
4.81509
6105
4.81528
6017
4.81546
5929
4.81565
5982
4.81584
5984
4.81602
5999
4.81621
5866
4.8164
5845
4.81658
5826
4.81677
5908
4.81695
5852
4.81714
5832
4.81733
5800
4.81751
5868
4.8177
5926
4.81788
5860
4.81807
5929
4.81826
5834
4.81844
5866
4.81863
5768
4.81882
5819
4.819
5775
4.81919
5787
4.81937
5792
4.81956
5824
4.81975
5783
4.81993
5768
4.82012
5693
4.8203
5768
4.82049
5756
4.82068
5845
4.82086
5757
4.82105
5727
4.82123
5735
4.82142
5686
4.82161
5721
4.82179
5777
4.82198
5718
4.82217
5676
4.82235
5736
4.82254
5621
4.82272
5594
4.82291
5617
4.8231
5818
4.82328
5742
4.82347
5732
4.82365
5679
4.82384
5640
4.82403
5732
4.82421
5687
4.8244
5694
4.82458
5807
4.82477
5724
4.82496
5569
4.82514
5578
4.82533
5702
4.82552
5639
4.8257
5672
4.82589
5616
4.82607
5701
4.82626
5664
4.82645
5533
4.82663
5638
4.82682
5642
4.827
5680
4.82719
5699
4.82738
5725
4.82756
5674
4.82775
5654
4.82793
5706
4.82812
5680
4.82831
5719
4.82849
5850
4.82868
5782
4.82887
5710
4.82905
5654
4.82924
5631
4.82942
5725
4.82961
5643
4.8298
5719
4.82998
5756
4.83017
5667
4.83035
5716
4.83054
5705
4.83073
5757
4.83091
5777
4.8311
5674
4.83128
5579
4.83147
5742
4.83166
5643
4.83184
5662
4.83203
5647
4.83222
5775
4.8324
5664
4.83259
5808
4.83277
5725
4.83296
5692
4.83315
5693
4.83333
5551
4.83352
5673
4.8337
5691
4.83389
5661
4.83408
5790
4.83426
5778
4.83445
5728
4.83463
5738
4.83482
Au 4f/6
shau3
2023
6
10
9
42
9
0
9
Casa Info Follows
0
0
0
0
shau3.vms Dir:D:\Google Drive\1 Academic\0 Berkeley\0 Long\B30 XPS\20230609 march of the pafs\
   XPS     Spectrum    Lens Mode:Hybrid   Resolution:Pass energy 40    Iris(Aper):slot(Slot)
   Acqn. Time(s): 969        Sweeps: 15       Anode:Mono(Al (Mono))(75 W)   Step(meV): 100.0
   Dwell Time(ms): 458        Charge Neutraliser :On   Acquired On :23/06/10 09:42:09
XPS
60
3
4
0
Mono(Al (Mono))
1486.69
75
1e+037
1e+037
6000
6000
1e+037
1e+037
FAT
40
1e+037
-4.46
0
1e+037
1e+037
1e+037
1e+037
Au
4f
-1
Kinetic Energy
eV
1392.69
0.1
2
Intensity
d
Transmission
d
pulse counting
0.458
15
0
1e+037
1e+037
1e+037
1
MFP Exponent
d
-0.7414
282
13702
27226
5.02032
5.04585
14122
5.02032
14141
5.0205
14104
5.02069
14180
5.02087
14222
5.02105
14319
5.02123
14280
5.02142
14162
5.0216
14039
5.02178
14077
5.02196
14387
5.02214
14303
5.02233
14327
5.02251
14395
5.02269
14324
5.02287
14404
5.02306
14386
5.02324
14276
5.02342
14496
5.0236
14337
5.02379
14368
5.02397
14465
5.02415
14505
5.02433
14678
5.02452
14618
5.0247
14790
5.02488
14760
5.02506
14917
5.02524
14939
5.02543
15022
5.02561
15185
5.02579
15505
5.02597
15624
5.02616
15708
5.02634
16016
5.02652
16037
5.0267
16463
5.02689
17162
5.02707
17722
5.02725
18137
5.02743
18762
5.02762
19680
5.0278
20314
5.02798
21292
5.02816
22017
5.02834
22553
5.02853
23267
5.02871
23681
5.02889
24351
5.02907
24868
5.02926
25113
5.02944
24881
5.02962
24280
5.0298
24268
5.02999
23595
5.03017
22911
5.03035
22210
5.03053
21949
5.03071
21805
5.0309
22146
5.03108
22279
5.03126
22380
5.03144
22575
5.03163
22266
5.03181
21535
5.03199
20690
5.03217
19654
5.03236
18769
5.03254
17906
5.03272
17477
5.0329
17304
5.03308
17429
5.03327
17790
5.03345
18031
5.03363
18568
5.03381
19055
5.034
19847
5.03418
20671
5.03436
21404
5.03454
22348
5.03473
23095
5.03491
23904
5.03509
24806
5.03527
25606
5.03546
26146
5.03564
26867
5.03582
27226
5.036
27150
5.03618
27096
5.03637
26627
5.03655
26147
5.03673
25262
5.03691
24667
5.0371
23934
5.03728
23324
5.03746
23089
5.03764
23099
5.03783
23613
5.03801
23859
5.03819
23626
5.03837
23356
5.03856
21996
5.03874
20638
5.03892
18970
5.0391
17923
5.03928
16986
5.03947
16138
5.03965
15667
5.03983
15327
5.04001
15112
5.0402
14744
5.04038
14706
5.04056
14491
5.04074
14141
5.04093
14004
5.04111
13996
5.04129
13921
5.04147
14011
5.04166
13959
5.04184
13941
5.04202
14110
5.0422
14009
5.04238
13811
5.04257
13814
5.04275
13734
5.04293
13850
5.04311
13702
5.0433
13858
5.04348
13928
5.04366
13893
5.04384
13738
5.04403
13953
5.04421
13915
5.04439
14164
5.04457
13985
5.04475
13843
5.04494
14150
5.04512
14163
5.0453
14183
5.04548
13895
5.04567
13868
5.04585
C 1s/7
shau3
2023
6
10
10
3
55
0
9
Casa Info Follows
0
0
0
0
shau3.vms Dir:D:\Google Drive\1 Academic\0 Berkeley\0 Long\B30 XPS\20230609 march of the pafs\
   XPS     Spectrum    Lens Mode:Hybrid   Resolution:Pass energy 40    Iris(Aper):slot(Slot)
   Acqn. Time(s): 444        Sweeps: 10       Anode:Mono(Al (Mono))(75 W)   Step(meV): 100.0
   Dwell Time(ms): 260        Charge Neutraliser :On   Acquired On :23/06/10 10:03:55
XPS
60
3
4
0
Mono(Al (Mono))
1486.69
75
1e+037
1e+037
6000
6000
1e+037
1e+037
FAT
40
1e+037
-4.46
0
1e+037
1e+037
1e+037
1e+037
C
1s
-1
Kinetic Energy
eV
1191.69
0.1
2
Intensity
d
Transmission
d
pulse counting
0.2597
10
0
1e+037
1e+037
1e+037
1
MFP Exponent
d
-0.7414
342
4623
38685
4.65677
4.70066
6990
4.65677
6989
4.65703
7018
4.65729
7167
4.65754
7040
4.6578
7106
4.65806
7108
4.65832
7103
4.65858
7035
4.65884
6938
4.65909
6930
4.65935
6944
4.65961
6999
4.65987
6928
4.66013
6947
4.66038
6993
4.66064
6996
4.6609
7096
4.66116
6969
4.66142
6943
4.66167
7057
4.66193
6988
4.66219
7014
4.66245
7026
4.66271
6936
4.66297
7012
4.66322
7075
4.66348
7092
4.66374
7141
4.664
7339
4.66426
7201
4.66452
7187
4.66477
7222
4.66503
7238
4.66529
7314
4.66555
7333
4.66581
7412
4.66606
7287
4.66632
7356
4.66658
7585
4.66684
7643
4.6671
7644
4.66735
7709
4.66761
7752
4.66787
7780
4.66813
7895
4.66839
8057
4.66865
8126
4.6689
8179
4.66916
8056
4.66942
8167
4.66968
8374
4.66994
8373
4.67019
8454
4.67045
8460
4.67071
8508
4.67097
8430
4.67123
8410
4.67149
8230
4.67174
8285
4.672
8092
4.67226
8032
4.67252
7884
4.67278
7788
4.67303
7545
4.67329
7550
4.67355
7357
4.67381
7318
4.67407
7405
4.67432
7276
4.67458
7281
4.67484
7174
4.6751
7193
4.67536
7286
4.67562
7400
4.67587
7314
4.67613
7415
4.67639
7656
4.67665
7876
4.67691
7972
4.67717
8155
4.67742
8494
4.67768
8701
4.67794
9102
4.6782
9509
4.67846
10002
4.67871
10477
4.67897
11299
4.67923
11973
4.67949
12758
4.67975
13634
4.68001
14426
4.68026
15358
4.68052
15993
4.68078
16625
4.68104
17032
4.6813
17560
4.68155
17928
4.68181
18237
4.68207
18720
4.68233
19187
4.68259
19776
4.68284
20488
4.6831
21436
4.68336
22784
4.68362
23969
4.68388
25766
4.68414
27640
4.68439
29583
4.68465
31923
4.68491
33384
4.68517
35178
4.68543
36969
4.68568
37642
4.68594
38561
4.6862
38677
4.68646
38685
4.68672
37672
4.68698
36426
4.68723
34228
4.68749
31867
4.68775
28965
4.68801
26471
4.68827
23443
4.68852
20743
4.68878
17930
4.68904
15612
4.6893
13694
4.68956
11616
4.68982
10160
4.69007
8842
4.69033
7832
4.69059
6986
4.69085
6480
4.69111
5903
4.69136
5751
4.69162
5482
4.69188
5180
4.69214
5113
4.6924
5144
4.69266
5077
4.69291
4884
4.69317
4983
4.69343
5078
4.69369
5040
4.69395
4978
4.6942
4876
4.69446
4924
4.69472
4925
4.69498
4818
4.69524
4804
4.69549
4820
4.69575
4934
4.69601
4840
4.69627
4808
4.69653
4762
4.69679
4768
4.69704
4781
4.6973
4731
4.69756
4658
4.69782
4741
4.69808
4623
4.69833
4712
4.69859
4761
4.69885
4778
4.69911
4766
4.69937
4658
4.69963
4736
4.69988
4710
4.70014
4726
4.7004
4784
4.70066
O KLL/8
shau3
2023
6
10
10
14
3
0
9
Casa Info Follows
0
0
0
0
shau3.vms Dir:D:\Google Drive\1 Academic\0 Berkeley\0 Long\B30 XPS\20230609 march of the pafs\
   XPS     Spectrum    Lens Mode:Hybrid   Resolution:Pass energy 40    Iris(Aper):slot(Slot)
   Acqn. Time(s): 810        Sweeps: 10       Anode:Mono(Al (Mono))(75 W)   Step(meV): 1000.0
   Dwell Time(ms): 988        Charge Neutraliser :On   Acquired On :23/06/10 10:14:03
XPS
60
3
4
0
Mono(Al (Mono))
1486.69
75
1e+037
1e+037
6000
6000
1e+037
1e+037
FAT
40
1e+037
-4.46
0
1e+037
1e+037
1e+037
1e+037
O
KLL
-1
Kinetic Energy
eV
450
1
2
Intensity
d
Transmission
d
pulse counting
0.9877
10
0
1e+037
1e+037
1e+037
1
MFP Exponent
d
-0.7414
164
98133
121504
4.5464
4.69339
105697
4.69339
106128
4.69041
105678
4.68742
105098
4.68444
105411
4.68145
105618
4.67847
105918
4.67549
106195
4.6725
106924
4.66952
106972
4.66653
106627
4.66366
106508
4.66192
106753
4.66018
106899
4.65844
106931
4.6567
107419
4.65496
107938
4.65322
108091
4.65148
108244
4.64974
107764
4.648
108491
4.64626
108194
4.64452
108209
4.64278
108272
4.64104
108294
4.6393
108934
4.63756
108921
4.63582
108664
4.63408
108598
4.63234
108488
4.6306
108767
4.62886
109402
4.62712
108956
4.62539
109564
4.62365
110360
4.62191
110671
4.62017
111020
4.61843
111277
4.61669
111778
4.61495
111808
4.61321
112949
4.61147
112742
4.60973
112519
4.60799
111943
4.60625
110787
4.60451
110020
4.60277
109263
4.60103
109282
4.59929
108763
4.59755
108363
4.59581
108246
4.59407
107702
4.59233
107875
4.59059
108191
4.58885
109181
4.58711
110128
4.58537
110393
4.58363
111622
4.58189
113266
4.58015
115580
4.57841
118226
4.5767
120878
4.57526
121504
4.57382
119124
4.57237
115797
4.57093
112382
4.56949
109870
4.56804
107928
4.5666
106732
4.56516
104508
4.56371
102550
4.56227
101138
4.56083
100191
4.55938
99187
4.55794
99200
4.5565
99154
4.55506
99056
4.55361
99176
4.55217
99196
4.55073
98133
4.54928
98793
4.54784
98850
4.5464
In 3d/9
shau3
2023
6
10
10
29
19
0
9
Casa Info Follows
0
0
0
0
shau3.vms Dir:D:\Google Drive\1 Academic\0 Berkeley\0 Long\B30 XPS\20230609 march of the pafs\
   XPS     Spectrum    Lens Mode:Hybrid   Resolution:Pass energy 40    Iris(Aper):slot(Slot)
   Acqn. Time(s): 600        Sweeps: 10       Anode:Mono(Al (Mono))(75 W)   Step(meV): 100.0
   Dwell Time(ms): 298        Charge Neutraliser :On   Acquired On :23/06/10 10:29:19
XPS
60
3
4
0
Mono(Al (Mono))
1486.69
75
1e+037
1e+037
6000
6000
1e+037
1e+037
FAT
40
1e+037
-4.46
0
1e+037
1e+037
1e+037
1e+037
In
3d
-1
Kinetic Energy
eV
1027.69
0.1
2
Intensity
d
Transmission
d
pulse counting
0.2985
10
0
1e+037
1e+037
1e+037
1
MFP Exponent
d
-0.7414
402
10421
102650
4.60709
4.62395
24918
4.60709
25090
4.60717
25074
4.60726
25254
4.60734
24772
4.60743
25026
4.60751
25037
4.60759
25071
4.60768
25036
4.60776
25314
4.60785
25296
4.60793
25435
4.60802
25674
4.6081
25888
4.60818
25998
4.60827
26074
4.60835
26270
4.60844
26366
4.60852
26537
4.60861
26633
4.60869
26752
4.60878
26742
4.60886
27085
4.60894
27640
4.60903
27757
4.60911
28140
4.6092
28358
4.60928
28487
4.60937
28746
4.60945
28911
4.60953
29362
4.60962
29618
4.6097
29897
4.60979
30114
4.60987
30453
4.60996
30122
4.61004
30097
4.61012
29587
4.61021
29504
4.61029
28804
4.61038
28333
4.61046
28104
4.61055
27725
4.61063
27938
4.61071
28241
4.6108
28614
4.61088
29406
4.61097
30730
4.61105
32028
4.61114
33771
4.61122
35910
4.6113
38778
4.61139
42134
4.61147
45315
4.61156
49156
4.61164
53363
4.61173
57953
4.61181
61603
4.6119
65663
4.61198
69353
4.61206
72414
4.61215
75360
4.61223
77624
4.61232
78921
4.6124
79725
4.61249
80016
4.61257
79821
4.61265
78145
4.61274
76591
4.61282
75184
4.61291
74252
4.61299
73771
4.61308
75000
4.61316
76604
4.61324
77303
4.61333
75535
4.61341
70720
4.6135
62898
4.61358
53420
4.61367
43906
4.61375
35789
4.61383
29851
4.61392
25971
4.614
23580
4.61409
22229
4.61417
21101
4.61426
20250
4.61434
19712
4.61442
19147
4.61451
18570
4.61459
18235
4.61468
18077
4.61476
17820
4.61485
17684
4.61493
17572
4.61501
17319
4.6151
17301
4.61518
17204
4.61527
17132
4.61535
16765
4.61544
17120
4.61552
17023
4.6156
17123
4.61569
17197
4.61577
17157
4.61586
17214
4.61594
17052
4.61603
17419
4.61611
17490
4.6162
17459
4.61628
17838
4.61636
18136
4.61645
18352
4.61653
18451
4.61662
18783
4.6167
19255
4.61679
19818
4.61687
20710
4.61695
21568
4.61704
22520
4.61712
23975
4.61721
25398
4.61729
27326
4.61738
29547
4.61746
32245
4.61754
35790
4.61763
39414
4.61771
43632
4.6178
48481
4.61788
53983
4.61797
60055
4.61805
66329
4.61813
72655
4.61822
78222
4.6183
83397
4.61839
88554
4.61847
92794
4.61856
96358
4.61864
99142
4.61872
101803
4.61881
102650
4.61889
102306
4.61898
101107
4.61906
99488
4.61915
97052
4.61923
95125
4.61932
93933
4.6194
94392
4.61948
96459
4.61957
98030
4.61965
97940
4.61974
93638
4.61982
84461
4.6199
71795
4.61999
57685
4.62007
44620
4.62016
34518
4.62024
27897
4.62033
23333
4.62041
20346
4.6205
18365
4.62058
16880
4.62066
16015
4.62075
15059
4.62083
14374
4.62092
13854
4.621
13376
4.62109
13153
4.62117
12929
4.62125
12475
4.62134
12152
4.62142
11968
4.62151
11937
4.62159
11840
4.62168
11741
4.62176
11517
4.62184
11359
4.62193
11445
4.62201
11245
4.6221
11271
4.62218
11196
4.62227
11011
4.62235
10953
4.62243
11093
4.62252
10928
4.6226
10860
4.62269
10729
4.62277
10766
4.62286
10983
4.62294
10827
4.62302
10824
4.62311
10859
4.62319
10767
4.62328
10694
4.62336
10539
4.62345
10561
4.62353
10571
4.62362
10421
4.6237
10610
4.62378
10488
4.62387
10662
4.62395
survey/10
shau3
2023
6
10
10
42
22
0
9
Casa Info Follows
0
0
0
0
shau3.vms Dir:D:\Google Drive\1 Academic\0 Berkeley\0 Long\B30 XPS\20230609 march of the pafs\
   XPS     Spectrum    Lens Mode:Hybrid   Resolution:Pass energy 160   Iris(Aper):slot(Slot)
   Acqn. Time(s): 121        Sweeps: 1        Anode:Mono(Al (Mono))(75 W)   Step(meV): 1000.0
   Dwell Time(ms): 100        Charge Neutraliser :On   Acquired On :23/06/10 10:42:22
XPS
60
3
4
0
Mono(Al (Mono))
1486.69
75
1e+037
1e+037
6000
6000
1e+037
1e+037
FAT
160
1e+037
-4.46
0
1e+037
1e+037
1e+037
1e+037
Wide
None
-1
Kinetic Energy
eV
286.69
1
2
Intensity
d
Transmission
d
pulse counting
0.1
1
0
1e+037
1e+037
1e+037
1
MFP Exponent
d
-0.7414
0
27.6167
10309
10047
10164
10241
10400
10363
10482
10476
10340
10453
10377
10374
10223
10367
10272
10207
10249
10266
10039
9995
9955
10062
10239
10299
10112
10129
10157
10231
10245
10092
10236
10213
10287
10356
10374
10323
10355
10267
10235
10272
10325
10357
10216
10198
10321
10294
10284
10201
10289
10156
10337
10339
10257
10176
10278
10191
10012
10305
10155
10013
9851
9715
9906
9747
9579
9616
9551
9435
9430
9457
9441
9418
9429
9403
9286
9272
9432
9477
9333
9463
9453
9452
9603
9630
9728
9719
9566
9578
9737
9755
9785
9592
9901
9645
9720
9769
9719
9608
9732
9761
9824
9738
9645
9721
9682
9625
9697
9735
9964
10083
10341
10989
11242
11414
11541
11434
11042
10791
10560
10543
10449
10051
9600
9464
9004
8677
8396
8180
8023
7925
7928
7993
7991
7929
8045
7951
7910
7917
8074
8097
7997
8058
8104
7989
8013
8000
8018
7949
7912
7964
8005
8022
7901
7967
8135
7962
7944
7946
8052
8018
8023
7901
8059
8180
8065
8193
8162
8096
8177
8161
8196
8260
8187
8201
8258
8209
8305
8072
8352
8303
8258
8224
8357
8292
8432
8331
8447
8500
8485
8601
8418
8533
8441
8459
8613
8675
8614
8723
8652
8549
8589
8778
8810
8737
8904
8765
8854
9048
8878
8826
8693
8673
8723
8686
8629
8536
8537
8616
8717
8687
8890
9102
9131
9327
9581
9758
9555
9363
9121
8901
8734
8703
8631
8410
8275
8177
8076
8031
8071
7995
8061
7990
7878
7902
8111
7994
8114
8032
8028
7991
8043
8099
8036
8097
8127
8052
7982
7945
8005
8199
8204
8189
8143
8138
8175
8146
8126
8181
8347
8098
8104
8160
8242
8213
8255
8210
8272
8287
8286
8271
8247
8272
8228
8236
8337
8268
8367
8348
8340
8297
8371
8369
8362
8423
8369
8287
8441
8429
8433
8379
8407
8547
8337
8405
8412
8295
8270
8420
8497
8555
8501
8452
8455
8545
8511
8543
8528
8482
8555
8535
8578
8555
8467
8519
8606
8612
8594
8729
8626
8624
8707
8591
8567
8713
8708
8689
8592
8750
8741
8853
8784
8752
8646
8616
8736
8725
8894
8762
8779
8755
8852
8848
8881
8822
8815
8765
8977
8889
9045
9069
9012
9026
8870
8917
8974
8984
9031
9048
9025
9116
9290
9380
9409
9435
9249
9237
9231
9058
8927
9016
8872
8851
8761
8719
8870
8813
8789
8783
8820
8744
8927
8757
8757
8884
8924
8905
8881
8822
8913
8835
9004
8953
8935
8877
8719
8775
8874
8962
8798
8886
8938
8948
9024
8992
9059
8896
8925
8956
8787
9063
9198
9082
9030
9057
8950
9139
9202
9102
9220
9226
9103
9167
9234
9187
9124
9247
9245
9234
9317
9232
9284
9232
9179
9297
9311
9337
9232
9217
9293
9309
9444
9484
9277
9292
9233
9359
9304
9422
9442
9313
9337
9331
9280
9465
9522
9526
9520
9442
9580
9498
9453
9645
9530
9597
9511
9571
9588
9542
9591
9665
9599
9685
9715
9666
9682
9671
9524
9450
9627
9575
9670
9713
9962
10123
10562
11360
11899
11725
11118
10438
9679
9366
9245
9250
9095
9201
9282
9223
9184
9234
9231
9278
9254
9289
9311
9344
9347
9278
9159
9247
9177
9176
9304
9150
9219
9126
8913
8811
8922
9313
9688
10274
11400
12761
13507
13127
11674
10145
9157
8621
8527
8280
8052
8007
7809
7852
7749
7889
7741
7849
7812
7855
7796
7790
7809
7768
7844
7957
7940
7916
7863
7886
7858
7709
7760
7851
7758
7886
7910
7785
7875
7874
7901
7812
7820
7872
7830
7898
8084
7912
7991
8062
7988
7854
7939
7889
7846
8034
8148
8001
8047
7971
8059
7990
8141
8050
8021
8103
8200
8368
8117
8267
8193
8195
8227
8242
8222
8331
8244
8180
8271
8192
8259
8464
8356
8327
8352
8370
8337
8305
8409
8356
8441
8448
8451
8330
8523
8545
8452
8429
8474
8511
8446
8528
8413
8584
8610
8500
8644
8571
8513
8520
8728
8831
8746
8706
8803
8823
8895
8879
8946
9030
8908
8892
8884
8750
8721
8566
8421
8419
8422
8350
8215
8302
8316
8619
9104
10378
12309
13448
12914
10805
8871
8018
7921
8076
7958
7859
7979
7922
7954
7960
8010
7943
7997
7897
7910
8034
8042
8115
7850
7908
8022
8030
8181
8153
8144
8034
8112
8071
8091
8135
8160
8031
7950
8123
8093
7985
8126
8163
8055
8205
8262
8254
8187
8168
8155
8250
8493
8353
8261
8321
8504
8597
8533
8557
8554
8639
8603
8663
8806
8722
8802
8822
8938
8965
9140
9229
8608
7922
7691
7787
7796
8062
8716
9532
11481
16419
19588
16129
9440
6317
6420
8531
14464
22326
23022
14609
6471
3889
3362
3190
3097
3058
2993
3010
3016
3071
2995
3017
3049
3024
3028
2955
2996
3008
2999
3000
2987
3055
2953
2919
2983
3045
2920
2976
2960
3053
3060
3097
3029
3054
3064
3091
3121
3014
3072
3112
3154
3224
3257
3181
3134
2995
3091
3107
3221
3077
3084
3022
3164
3096
3079
3018
2996
3081
3163
3148
3146
3106
3135
3123
3127
3102
3185
3198
3180
3164
3161
3154
3169
3209
3224
3237
3178
3215
3281
3179
3263
3247
3214
3262
3384
3358
3394
3561
3542
3539
3478
3415
3339
3215
3159
3213
3208
3278
3215
3230
3271
3311
3360
3392
3513
3587
3708
3668
3578
3429
3260
3237
3208
3215
3123
3118
2949
3068
3012
2988
3064
3101
3109
3159
3097
3070
3099
3089
3090
3127
3198
3141
3150
3181
3166
3239
3177
3169
3120
3120
3033
3041
2905
2820
2691
2620
2551
2455
2459
2438
2577
2696
2835
2860
2858
3178
4208
5964
8369
9085
6206
3172
2019
1786
1794
1717
1667
1674
1720
1698
1701
1706
1736
1717
1703
1696
1718
1752
1732
1682
1653
1658
1648
1743
1675
1716
1717
1717
1720
1732
1714
1686
1659
1726
1666
1745
1746
1775
1749
1738
1700
1714
1696
1753
1756
1711
1707
1795
1810
1834
1841
1897
1906
1858
1895
1888
1838
1756
1735
1753
1784
1761
1742
1811
1799
1793
1807
1774
1745
1790
1785
1775
1791
1797
1769
1813
1791
1731
1757
1794
1895
1866
1878
1920
1938
1876
1820
1807
1799
1838
1828
1847
1870
1856
1861
1851
1777
1818
1797
1840
1870
1804
1830
1812
1841
1921
1788
1836
1824
1828
1917
1831
1841
1898
2018
2078
2085
2019
1944
1985
1975
1935
1938
1895
1865
1848
1853
1888
1926
1873
1870
1933
1894
1919
1882
1915
1947
1934
1893
1889
1898
1985
1914
1918
1948
1955
1994
2032
1947
2025
2028
2006
1935
2007
2045
2068
2129
2186
2268
2244
2191
2234
2091
2035
1996
1955
1882
1944
1931
1918
1874
1861
1884
2034
1966
1901
1892
1959
1965
2021
2032
1946
1963
1918
1929
1983
1926
1942
1957
1943
2074
2230
2499
2847
2960
2857
2881
3146
3053
2568
2132
1957
1897
1945
1949
1766
1701
1642
1493
1398
1355
1250
1128
1121
1049
1039
972
955
986
950
950
960
995
991
956
1004
1005
936
924
961
945
881
945
916
918
953
954
956
1001
1017
1053
1055
1028
1050
977
983
954
966
963
956
940
1043
1219
1289
1169
953
829
769
810
858
896
1205
1943
3302
4552
4313
2539
823
380
287
271
251
250
252
324
387
415
373
349
248
146
103
70
38
11
2
2
0
38.0316
end of experiment